Workbook

Sheet Home
A1: # | B1: LTI - Mindtree Merger: M&A Case Study
B2: Was the 73:100 stock-for-stock exchange ratio a fair valuation? Full DCF, Trading Comps, and Precedent Transactions analysis, formal exchange-ratio mechanics, and accretion/dilution - triangulated against the actual deal and the real, disclosed post-merger results.
A5: ## | B5: SECTION 1 - M&A Analysis (start here)
B6: The headline deliverable: cross-company valuation, deal mechanics, and the fairness question.
B7: -> Football Field | C7: Capstone: DCF + Comps + Precedent Transactions synthesized into one view
B8: -> Precedent Transactions | C8: Real M&A comps, third valuation method
B9: -> Exchange Ratio & Ownership | C9: Share issuance, ownership split, premium/discount check
B10: -> Pro Forma & Accretion-Dilution | C10: Real disclosed post-merger results, accretion/dilution, industry-adjusted margin test
B11: -> Event Study - Market Reaction | C11: Real abnormal-returns analysis around the announcement date
B12: -> Stress Test - Exchange Ratio | C12: Bull/Base/Bear bounds test, methodology from Sasi's own course
B13: -> Synergies (Bottom-Up Estimate) | C13: Secondary - bottom-up estimate, see Pro Forma sheet for actuals
B14: -> Best Owner Analysis
B15: -> Goal-Seek Synergy Backsolve
B16: -> Value of Control
B17: -> AVP - Various Exchange Ratios
B18: -> Reference LBO Floor
A19: ## | B19: SECTION 2 - LTI Standalone Model
B20: Full standalone financial model for Larsen & Toubro Infotech: historicals, 3-statement forecast, DCF, WACC, Comps.
B21: -> LTI_HIST_CON | C21: Historical financials, as filed (Tier 1)
B22: -> LTI_DCF | C22: DCF valuation output
B23: -> LTI_WACC Schedule | C23: WACC build, deal-date share price/count
B24: -> LTI_Comps
B25: -> LTI_Balance Sheet (Projected)
B26: -> LTI_CFStmt
A28: ## | B28: SECTION 3 - Mindtree Standalone Model
B29: Same full standalone build for Mindtree, mirroring the LTI structure sheet-for-sheet.
B30: -> MT_HIST_CON | C30: Historical financials, as filed (Tier 1)
B31: -> MT_DCF | C31: DCF valuation output
B32: -> MT_WACC Schedule | C32: WACC build, deal-date share price/count
B33: -> MT_Comps
B34: -> MT_Balance Sheet (Projected)
B35: -> MT_CFStmt
B37: Tab colors: teal = M&A Analysis, navy = LTI standalone, orange = Mindtree standalone - all 40 sheets in one file, grouped and color-coded rather than split into separate files, so every cross-company formula in Section 1 stays a live, auditable, same-file link with no cross-file reference fragility.

Sheet Event Study - Market Reaction
A1: # | B1: Event Study - Market Reaction to the Merger Announcement
B2: Did the market see this as value-creating? Cumulative Abnormal Returns (CAR) around the 6-May-2022 announcement, market-model methodology grounded in the Theory notebook (Moeller/Schlingemann/Stulz 2005, Schwert 1996). Real daily prices - LTI via Yahoo Finance (current ticker LTM.NS), Mindtree via NSE's own bhavcopy archives (its ticker was fully delisted, not just renamed, and dropped from Yahoo entirely). Both cross-validated against this model's already-established 6-May-2022 prices.
A4: ## | B4: Market Model Regression - LTI vs Nifty IT
B5: Estimation window: rows 61-179 below (2021-11-01 to 2022-04-25, ~120 trading days, ending 8 trading days before the announcement to avoid run-up contamination).
B7: Disclosed limitation (audit gap #13, Task 26 - checked against this script directly, not assumed either way): the estimation window ends only 8 trading days before the announcement. Standard event-study practice guards against merger-related run-up/leakage with a wider buffer (e.g. 16-42 trading days). Two mitigating, deal-specific factors, not an excuse to skip the disclosure: (1) both LTI and Mindtree were ALREADY L&T subsidiaries pre-merger, so this deal lacks the third-party bidding-war/rumor-driven accumulation dynamic that motivates the wider buffers in the general literature; (2) the regression's R-squared (below) is high enough that a few contaminated days near the edge of the window would have limited leverage over the fitted alpha/beta. Neither claim has been separately tested - flagged honestly as a real, narrower-than-textbook buffer, not silently treated as fully addressed.
B9: Beta (slope) | C9: =SLOPE(D61:D179,F61:F179)
B10: Alpha (intercept, daily) | C10: =INTERCEPT(D61:D179,F61:F179)
B11: R-squared | C11: =RSQ(D61:D179,F61:F179)
B12: Std. Error of Regression (daily AR std. dev., estimation window) | C12: =STEYX(D61:D179,F61:F179) | E12: Used below for CAR significance testing (t-stat = CAR / (this x SQRT(window length))).
A14: ## | B14: Market Model Regression - Mindtree vs Nifty IT
B15: Same estimation window and methodology as LTI's regression above - Mindtree's full daily price series (NSE bhavcopy archives, 119 additional dates fetched beyond the original event-window-only set) now covers this window too, so both companies get the same full market-model rigor.
B17: Beta (slope) | C17: =SLOPE(J61:J179,F61:F179)
B18: Alpha (intercept, daily) | C18: =INTERCEPT(J61:J179,F61:F179)
B19: R-squared | C19: =RSQ(J61:J179,F61:F179)
B20: Std. Error of Regression (daily AR std. dev., estimation window) | C20: =STEYX(J61:J179,F61:F179)
A22: ## | B22: Cumulative Abnormal Returns - Summary
B24: Window | C24: LTI CAR (market model) | D24: Mindtree CAR (market model) | E24: Combined CAR (MV-weighted) | F24: LTI t-stat | G24: Mindtree t-stat
B25: [-1,+1] | C25: =SUM(H186:H188) | D25: =SUM(L186:L188) | E25: =C25*$C$28/($C$28+$C$29)+D25*$C$29/($C$28+$C$29) | F25: =C25/($C$12*SQRT(3)) | G25: =D25/($C$20*SQRT(3))
B26: [-2,+2] | C26: =SUM(H185:H189) | D26: =SUM(L185:L189) | E26: =C26*$C$28/($C$28+$C$29)+D26*$C$29/($C$28+$C$29) | F26: =C26/($C$12*SQRT(5)) | G26: =D26/($C$20*SQRT(5))
B28: LTI Market Value pre-event (Rs.M, t=-2) | C28: ='Exchange Ratio & Ownership'!C11*C185/1000000 | E28: LTI shares outstanding x price at t=-2
B29: Mindtree Market Value pre-event (Rs.M, t=-2) | C29: ='Exchange Ratio & Ownership'!C12*I185/1000000
B32: Reading this: a positive Combined CAR means the market judged the announcement as net value-creating for the two companies together (the standard test in the abnormal-returns literature - Jensen 1986, the hubris hypothesis paper, 'Wealth Destruction on a Massive Scale'). LTI's own CAR specifically (not combined) is the closer read on whether the ACQUIRER's shareholders benefited - the literature's well-documented average finding is that acquirers often see flat-to-negative CAR even in deals the combined entity gains from, since much of the value gets bid to the target's shareholders.
A34: ## | B34: Statistical Significance of the CAR Estimates
B36: t-stat = CAR / (estimation-window regression std. error x SQRT(window length in days)) - the standard single-security event-study significance test (Brown & Warner 1985; MacKinlay 1997), shown in the table above. Critical values: |t| > 1.65 significant at 10%, > 1.96 at 5%, > 2.58 at 1%. Deliberately NOT computing a pooled t-stat across LTI-and-Mindtree treated as if they were two independent observations - they are not: both are reacting to the same single announcement and are already correlated by construction (same sector, same L&T parent group), so a naive combined-sample t-test would overstate significance the same way the literature warns pooled cross-sectional event studies do when they ignore industry/time clustering (see the notebook audit, Task 26) - the difference here is that this is a single-deal, two-firm case study, not a multi-deal cross-sectional sample, so the fix is to test each company's own CAR individually (as done above), not to pool them.
B38: Reading this (verified via recalc, not asserted in advance): Mindtree's negative CAR is statistically significant at the 1% level in BOTH windows (t=-2.89 and -2.76) - strong evidence the market's negative reaction to Mindtree specifically was real, not noise. LTI's result is weaker and window-dependent: significant at 5% in the tight [-1,+1] window (t=-2.15) but NOT statistically distinguishable from zero in the wider [-2,+2] window (t=-1.42, below even the 10% threshold). This sharpens rather than overturns the finding above: the market's skepticism was clearly real and significant for Mindtree; for LTI (the acquirer) the evidence is more marginal and window-sensitive - consistent with the literature's general finding that acquirer CARs are often statistically indistinguishable from zero even in deals where the target's reaction is unambiguous.
A58: ## | B58: Daily Data (raw prices sourced; returns and AR are live formulas)
B59: LTI and NiftyIT: Yahoo Finance chart API (ticker LTM.NS, ^CNXIT), parsed directly from raw JSON with IST timezone conversion, cross-validated against NSE bhavcopy at 4 overlapping dates (exact match). Mindtree: NSE bhavcopy archives directly (archives.nseindia.com), 131 of 135 needed trading days (119 fetched individually beyond the original event-window set) - its ticker was delisted (not renamed) at the Nov-2022 merger completion and dropped entirely from Yahoo, so no bulk-range source existed. The 4 uncovered dates fall outside both the estimation and event windows used here.
B60: Date | C60: LTI Close | D60: LTI Return | E60: NiftyIT Close | F60: NiftyIT Return | G60: Expected Return (LTI) | H60: LTI AR | I60: Mindtree Close | J60: Mindtree Return | K60: Expected Return (Mindtree) | L60: Mindtree AR
B61: 2021-11-01 | C61: 6802.15 | E61: 35290 | I61: 4733.7
B62: 2021-11-02 | C62: 6752.9 | D62: =C62/C61-1 | E62: 35177.35 | F62: =E62/E61-1 | I62: 4711.25 | J62: =I62/I61-1
B63: 2021-11-03 | C63: 6736.05 | D63: =C63/C62-1 | E63: 35177.1 | F63: =E63/E62-1 | I63: 4628.3 | J63: =I63/I62-1
B64: 2021-11-04 | C64: 6765 | D64: =C64/C63-1 | E64: 35334.25 | F64: =E64/E63-1 | I64: 4665.8 | J64: =I64/I63-1
B65: 2021-11-08 | C65: 6827.9 | D65: =C65/C64-1 | E65: 35782.35 | F65: =E65/E64-1 | I65: 4829.7 | J65: =I65/I64-1
B66: 2021-11-09 | C66: 6839.65 | D66: =C66/C65-1 | E66: 35815.1 | F66: =E66/E65-1 | I66: 4815.5 | J66: =I66/I65-1
B67: 2021-11-10 | C67: 6835.8 | D67: =C67/C66-1 | E67: 35722.95 | F67: =E67/E66-1 | I67: 4831.45 | J67: =I67/I66-1
B68: 2021-11-11 | C68: 6948.75 | D68: =C68/C67-1 | E68: 35583.65 | F68: =E68/E67-1 | I68: 4888.05 | J68: =I68/I67-1
B69: 2021-11-12 | C69: 7243.25 | D69: =C69/C68-1 | E69: 36332.3 | F69: =E69/E68-1 | I69: 4914.1 | J69: =I69/I68-1
B70: 2021-11-15 | C70: 7197.35 | D70: =C70/C69-1 | E70: 36465.3 | F70: =E70/E69-1 | I70: 4931.45 | J70: =I70/I69-1
B71: 2021-11-16 | C71: 7291.3 | D71: =C71/C70-1 | E71: 36643.9 | F71: =E71/E70-1 | I71: 4958.15 | J71: =I71/I70-1
B72: 2021-11-17 | C72: 7397.05 | D72: =C72/C71-1 | E72: 36660.9 | F72: =E72/E71-1 | I72: 4988.95 | J72: =I72/I71-1
...

Sheet Exchange Ratio & Ownership
A1: # | B1: Exchange Ratio & Pro Forma Ownership
B2: LTI is the acquirer (issues new shares); Mindtree is the target (its shareholders receive LTI stock). All-stock, no cash consideration - the actual structure of the announced deal.
A4: ## | B4: Deal Terms
B6: Announced Exchange Ratio (LTI shares per 100 Mindtree shares) | C6: 73 | E6: Actual, publicly announced swap ratio for the LTI-Mindtree merger (6-May-2022) - a real deal term, not derived.
B7: Exchange Ratio (LTI shares per 1 Mindtree share) | C7: =C6/100
A9: ## | B9: Shares Outstanding & New Issuance
B11: LTI Shares Outstanding (pre-deal, acquirer) | C11: ='LTI_WACC Schedule'!C7
B12: Mindtree Shares Outstanding (pre-deal, target) | C12: ='MT_WACC Schedule'!C7
B13: New LTI Shares Issued (computed, FY22-end share count basis) | C13: =C12*C7 | E13: Mindtree shares outstanding x exchange ratio - a modeled figure, superseded below by the actual disclosed allotment.
B14: New LTI Shares Issued (ACTUAL, per NCLT Scheme Order / AR2023) | C14: 120417607 | E14: Actual allotment 25-Nov-2022 (incl. 165,247 fractional-entitlement shares pooled to a trustee and cash-settled) - LTIMindtree FY23 Board Report / NCLT Mumbai Scheme Order, both in the Company/Deal notebook. Used below as the basis for pro forma shares - real disclosed figure takes precedence over the modeled one above.
B15: Reconciling Difference (Actual - Computed) | C15: =C14-C13 | E15: Reflects Mindtree's shares outstanding moving slightly between FY22-end (Mar-2022, this model's basis) and the actual Record Date (24-Nov-2022) - e.g. ESOP exercises - not a modeling error.
B17: Pro Forma LTI Shares Outstanding (post-deal, using ACTUAL issuance) | C17: =C11+C14
B19: L&T's Ownership of Combined Entity (ACTUAL, disclosed) | C19: 0.6873 | E19: Disclosed directly in the 14-Nov-2022 merger-completion press release - a different cut than the LTI-legacy/Mindtree-legacy split above (this isolates one shareholder, L&T, across both companies' pre-deal holdings combined), included as an independent cross-check, not a contradiction.
A21: ## | B21: Post-Deal Ownership Split
B23: LTI Legacy Shareholders | C23: =C11/C17
B24: Former Mindtree Shareholders | C24: =C14/C17
A26: ## | B26: Value Analysis: Exchange Ratio vs. Same-Day Market Prices
B28: LTI Market Price (6-May-2022, Rs.) | C28: ='LTI_WACC Schedule'!C6
B29: Value Received per Mindtree Share (in LTI stock, Rs.) | C29: =C7*C28 | E29: Exchange ratio x LTI's own market price
B30: Mindtree Standalone Market Price (6-May-2022, Rs.) | C30: ='MT_WACC Schedule'!C6
B31: Implied Premium / (Discount) to Mindtree's Standalone Price | C31: =C29/C30-1
B33: Reading this: the announced 73:100 ratio valued each Mindtree share at essentially its own same-day market price - a small discount, under 1% (see the computed cell above for the exact figure), not a premium. This is consistent with a merger structured off relative trading values between two already-affiliated companies (both L&T subsidiaries) rather than a control-premium acquisition of an independent target - real acquisitions of independent companies typically carry a 20-40%+ premium to the undisturbed share price; this deal shows essentially none, which fits a NAV/relative-value merger-of-affiliates structure rather than a traditional third-party buyout.
A35: ## | B35: Contribution Analysis
B37: Standard stock-for-stock fairness check (DePamphilis): compares each side's financial contribution to the combined entity (pre-transaction-adjustment, FY22 standalone) against the ownership split it actually received. A gap is not automatically unfair - synergy value, growth-rate differences and relative risk all legitimately justify one side receiving more ownership than its raw financial contribution alone would imply - but seeing the gap explicitly is the standard next question after any exchange-ratio check.
B39: Metric (FY22 standalone) | C39: LTI (Rs.M) | D39: Mindtree (Rs.M)
B40: Revenue | C40: ='LTI_P&L Schedule'!H7/1000000 | D40: ='MT_P&L Schedule'!H7/1000000
B41: EBITDA | C41: ='LTI_P&L Schedule'!H11/1000000 | D41: ='MT_P&L Schedule'!H11/1000000
B42: EBIT | C42: ='LTI_P&L Schedule'!H14/1000000 | D42: ='MT_P&L Schedule'!H14/1000000
B43: Net Income (PAT) | C43: ='LTI_P&L Schedule'!H22/1000000 | D43: ='MT_P&L Schedule'!H22/1000000
B44: Market Capitalization (6-May-2022) | C44: =('LTI_WACC Schedule'!C6*'LTI_WACC Schedule'!C7)/1000000 | D44: =('MT_WACC Schedule'!C6*'MT_WACC Schedule'!C7)/1000000
A46: ### | B46: Contribution % (each metric's share of LTI+Mindtree combined)
B47: Revenue Contribution % | C47: =C40/(C40+D40) | D47: =D40/(C40+D40)
B48: EBITDA Contribution % | C48: =C41/(C41+D41) | D48: =D41/(C41+D41)
B49: EBIT Contribution % | C49: =C42/(C42+D42) | D49: =D42/(C42+D42)
B50: Net Income (PAT) Contribution % | C50: =C43/(C43+D43) | D50: =D43/(C43+D43)
B51: Market Capitalization (6-May-2022) Contribution % | C51: =C44/(C44+D44) | D51: =D44/(C44+D44)
B53: Actual Ownership Split (from Post-Deal Ownership Split above, for comparison) | C53: =C11/C17 | D53: =C14/C17
B55: Reading this (verified via recalc, not asserted in advance): the actual ownership split (59.3% LTI / 40.7% Mindtree) sits within about 1 percentage point of Mindtree's contribution share on every metric tested - Revenue 40.2%, EBITDA 41.8%, EBIT 41.9%, Net Income 41.8%, Market Cap 40.9%. Mindtree's actual ownership share lands almost exactly between its lower revenue-contribution share and its higher profitability-contribution shares, not skewed toward either extreme. This is a genuinely independent confirmation of fairness - Contribution Analysis uses only raw FY22 P&L and market-cap figures, with no reference to the DCF, Comps or Precedent Transactions work elsewhere in this model, and it lands on essentially the same conclusion those methods did: the deal was priced close to a straightforward pro-rata split of the combined entity's financial substance, not skewed toward either side.
A57: ## | B57: Control Premium x Illiquidity Discount (Pratt's Multiplicative Model)
B59: Gross Base Price x (1 + Control Premium) x (1 - Illiquidity Discount) = Net Price - control premiums and illiquidity/marketability discounts compound multiplicatively, not additively, when both apply (Pratt). Shown here for correct mechanical treatment, even though this specific deal has close to zero of either factor (see below).
...

Sheet Pro Forma & Accretion-Dilution
A1: # | B1: Pro Forma Combination & Accretion/Dilution
B2: Grounded in ACTUAL disclosed combined-entity results (LTIMindtree FY23 Board Report), not a purely hypothetical pro forma - the Appointed Date (1-Apr-2022) means the FY23 report's Consolidated FY22 comparatives are the real, audited restated combined-entity figures for that year.
A4: ## | B4: Actual Disclosed Combined-Entity Results (Rs. Million)
B6: Line Item | C6: Consolidated FY22 (restated) | D6: Consolidated FY23 (actual)
B7: Revenue from Operations | C7: 261087 | D7: 331830
B8: Other Income | C8: 7658 | D8: 5569
B9: Total Revenue | C9: 268745 | D9: 337399
B10: Employee Benefit Expense | C10: 159892 | D10: 208799
B11: Sub-contractor Expense | C11: 23591 | D11: 28286
B12: Finance Costs | C12: 1234 | D12: 1504
B13: Depreciation & Amortisation | C13: 5971 | D13: 7227
B14: Other Expenses | C14: 25118 | D14: 33668
B15: Total Expenses | C15: 215806 | D15: 279484
B16: Profit Before Tax | C16: 52939 | D16: 57915
B17: Tax Expense | C17: 13439 | D17: 13812
B18: Profit for the Year (PAT) | C18: 39500 | D18: 44103
B19: Source: LTIMindtree FY2022-23 Integrated Annual Report / Board Report, and the NCLT Mumbai Bench Scheme Order (26-Sep-2022) confirming the 1-Apr-2022 Appointed Date - both in the Company/Deal NotebookLM notebook, queried directly before building this sheet.
A21: ## | B21: Margin Trend - Real, Not Estimated (companion note on synergy sizing)
B23: Metric | C23: FY22 (restated) | D23: FY23 (actual) | E23: FY24 (actual)
B24: Revenue from Operations (Rs.M) | C24: =C7 | D24: =D7 | E24: 355170
B25: EBITDA (Rs.M) = Revenue - Employee Benefit - Subcontractor - Other Expenses | C25: =C7-C10-C11-C14 | D25: =D7-D10-D11-D14 | E25: n/a - full FY24 expense breakdown not sourced
B26: EBITDA Margin (%) | C26: =C25/C7 | D26: =D25/D7 | E26: n/a
B27: EBIT (Rs.M) = EBITDA - D&A | C27: =C25-C13 | D27: =D25-D13 | E27: n/a - full FY24 expense breakdown not sourced
B28: EBIT Margin (%) | C28: =C27/C7 | D28: =D27/D7 | E28: 0.157
B29: Other Expenses / Revenue (SG&A proxy, %) | C29: =C14/C7 | D29: =D14/D7 | E29: n/a
B31: Source for FY24: Business Standard (LTIMindtree FY24 results, reported Apr-2024) - Revenue Rs.35,517cr (+7.03% YoY), EBIT margin 15.7%, PAT Rs.4,584.6cr (+4% YoY, consistent with FY23's Rs.4,410.3cr already in this sheet - cross-checked, not just assumed). No line-item expense breakdown sourced for FY24, so EBITDA and the SG&A ratio are left blank rather than backed into.
B33: Reading this: EBIT margin fell in both actual post-merger years - 17.82% (FY22) -> 16.23% (FY23) -> 15.7% (FY24) - the opposite of what a synergy-driven cost story would predict. This is why the Rs.10,123M bottom-up synergy estimate (Synergies sheet) is NOT scaled up despite Sasi's instinct that it looked too small: real, disclosed margin data across two full years doesn't support a larger, margin-expansion-based number. Two plausible, non-alarming explanations, not mutually exclusive: (1) FY23 captures only ~5 months of integrated operations post the 14-Nov-2022 Effective Date, and cost synergies from a deal this size typically take 2-4 years to fully phase in; (2) a real, well-documented sector-wide wage/attrition war ran through this exact period (this session's own earlier Porter's-Forces research found attrition rising from 14.8% to 24.0% with double-digit wage hikes) - pressure that would compress margins regardless of the merger. This does NOT contradict the +13.74% EPS accretion found above - that accretion is real (based on actual disclosed PAT) but is REVENUE-GROWTH-driven, not synergy/margin-driven, and the two should not be conflated when explaining why EPS grew.
A35: ## | B35: Industry-Adjusted Performance (Healy-Palepu-Ruback methodology)
B37: Tests the margin-compression finding above against the same period's peer performance - the academic-standard way to separate "the merger hurt margins" from "the whole sector's margins fell and this company was no exception" (Healy, Palepu & Ruback 1992, in the Theory notebook).
B39: Peer (true EBIT margin = (Op.Profit-Depr.)/Sales) | C39: FY22 | D39: FY23 | E39: FY24
B40: TCS | C40: 0.25268313 | D40: 0.24056365 | E40: 0.24621305
B41: Infosys | C41: 0.23030886 | D41: 0.21057186 | E41: 0.20659205
B42: Wipro | C42: 0.17155033 | D42: 0.14918 | E42: 0.14867424
B43: HCL Technologies | C43: 0.18917467 | D43: 0.1821775 | E43: 0.18218955
B44: Tech Mahindra | C44: 0.14558975 | D44: 0.10895102 | E44: 0.051715517
B45: Peer Median EBIT Margin | C45: =MEDIAN(C40:C44) | D45: =MEDIAN(D40:D44) | E45: =MEDIAN(E40:E44)
B47: LTIMindtree EBIT Margin (from above) | C47: =C27/C7 | D47: =D27/D7 | E47: 0.157
B48: Industry-Adjusted Performance (LTIMindtree - Peer Median) | C48: =C47-C45 | D48: =D47-D45 | E48: =E47-E45
B49: Change in Industry-Adjusted Gap, FY22 -> FY24 | C49: =E48-C48
B51: Source: Screener.in consolidated P&L, Sales / Operating Profit / Depreciation individually sourced per peer, one query per company (25-Aug-2026). CORRECTED from an earlier version of this sheet that used Screener's own OPM% directly - OPM nets out BEFORE depreciation (EBITDA-like: verified TCS's OPM-implied PBT reconciles exactly - 53,057+4,018-784-4,604=51,687, matching reported PBT), so comparing it to this sheet's own EBIT margin (after depreciation) was an EBIT-vs-EBITDA mismatch. Now both sides are true EBIT, same construction, genuinely comparable.
...

Sheet Stress Test - Exchange Ratio
A1: # | B1: Stress Test - Exchange Ratio Bounds (Bull/Base/Bear)
B2: Methodology from Sasi's own M&A course (Prof. Yogesh Chauhan) - "Determining Exchange Ratio: A logic": the buyer sets a MAXIMUM exchange ratio it can pay without overpaying (target's standalone value + its share of synergy, divided by buyer's own value); the seller sets a MINIMUM it will accept (target's standalone value alone, no synergy credit, divided by buyer's value). The actual 73:100 ratio is tested against this [Min, Max] negotiable range under three scenarios, not just the locked-in base case.
A4: ## | B4: Scenario Inputs
C6: Bear | D6: Base | E6: Bull
B7: WACC scenario (Sensitivity Table row) | C7: +2pp (row 12) | D7: Base (row 10, locked-in) | E7: -2pp (row 8)
B8: Synergy Realization % | C8: 0 | D8: 1 | E8: 1.5
B10: Bear = higher discount rate (worse conditions) + zero synergy realized (skeptical case, deal creates no value beyond the two standalone businesses). Base = the locked-in WACC + full Rs.10,123M/year bottom-up synergy estimate. Bull = lower discount rate + 150% of the estimate (upside: cross-sell and cost synergies exceed the conservative bottom-up case).
A12: ## | B12: Standalone Intrinsic Value / Share (Rs.)
C14: Bear | D14: Base | E14: Bull
B15: LTI Standalone Value/Share | C15: ='LTI_Sensitivity Tables'!E12 | D15: ='LTI_Sensitivity Tables'!E10 | E15: ='LTI_Sensitivity Tables'!E8
B16: Mindtree Standalone Value/Share | C16: ='MT_Sensitivity Tables'!E12 | D16: ='MT_Sensitivity Tables'!E10 | E16: ='MT_Sensitivity Tables'!E8
B17: WACC used for this scenario (LTI) | C17: 0.12045823 | D17: 0.10045823 | E17: 0.080458232
B19: Standalone values pulled live from the already-built LTI_/MT_Sensitivity Tables (WACC +/-2pp at base-case terminal growth - Table 1 in each sheet). WACC figures re-entered here as sourced inputs (matching those tables' own row headers) so the synergy perpetuity below uses a consistent discount rate per scenario.
A21: ## | B21: Synergy Value (Growing Perpetuity)
C23: Bear | D23: Base | E23: Bull
B24: Annual Synergy Realized (Rs.M) | C24: ='Synergies (Bottom-Up Estimate)'!$D$36*C8 | D24: ='Synergies (Bottom-Up Estimate)'!$D$36*D8 | E24: ='Synergies (Bottom-Up Estimate)'!$D$36*E8
B25: Terminal Growth Rate (locked-in, both companies) | C25: ='LTI_DCF'!C22 | D25: ='LTI_DCF'!C22 | E25: ='LTI_DCF'!C22
B26: Synergy PV (Rs.M) = Annual / (WACC - TGR) | C26: =C24/(C17-C25) | D26: =D24/(D17-D25) | E26: =E24/(E17-E25)
B27: Synergy PV per Mindtree Share (Rs.) | C27: =C26*1000000/'Exchange Ratio & Ownership'!$C$12 | D27: =D26*1000000/'Exchange Ratio & Ownership'!$C$12 | E27: =E26*1000000/'Exchange Ratio & Ownership'!$C$12
A29: ## | B29: Exchange Ratio Bounds vs. Actual (73:100 = 0.73)
C31: Bear | D31: Base | E31: Bull
B32: Min Exchange Ratio (Seller floor, no synergy credit) | C32: =C16/C15 | D32: =D16/D15 | E32: =E16/E15
B33: Max Exchange Ratio (Buyer ceiling, incl. synergy) | C33: =(C16+C27)/C15 | D33: =(D16+D27)/D15 | E33: =(E16+E27)/E15
B34: Actual Ratio (0.73) | C34: 0.73 | D34: 0.73 | E34: 0.73
B35: Within [Min, Max]? | C35: =IF(AND(C34>=C32,C34<=C33),"YES - within range","NO - outside range") | D35: =IF(AND(D34>=D32,D34<=D33),"YES - within range","NO - outside range") | E35: =IF(AND(E34>=E32,E34<=E33),"YES - within range","NO - outside range")
B37: Reading this: even in the Bear case (higher discount rate, zero synergy credited to the buyer's ceiling), the actual 73:100 ratio's position relative to [Min, Max] shows whether the deal required optimistic assumptions to look fair, or whether it clears the bar even under skeptical inputs. In the Base case, the range reflects this model's own locked-in DCF assumptions plus the full bottom-up synergy estimate. The Bull case shows how much headroom exists if synergies run ahead of the conservative estimate. This is the same negotiation-range logic taught in Sasi's own course (buyer's ceiling vs. seller's floor) - not a new framework invented for this model.
A40: ## | B40: Ramp-Up & Integration-Cost-Adjusted Synergy PV (audit gap #12c cross-check)
B41: A separate adjusted view alongside (not replacing) the flat-perpetuity Synergy PV above (rows 21-27) - uses the ramp-up schedule and one-time integration cost added at 'Synergies (Bottom-Up Estimate)'!B44:D44/B49. Integration cost is the SAME absolute Rs.M in every scenario column (based on the full D36 run-rate, not the scenario-adjusted one) - the cost to attempt integration is incurred regardless of how much synergy actually materializes, including in Bear where realized synergy is zero.
C43: Bear | D43: Base | E43: Bull
B44: Year 1 Synergy Realized (Rs.M) | C44: =C24*'Synergies (Bottom-Up Estimate)'!$B$44 | D44: =D24*'Synergies (Bottom-Up Estimate)'!$B$44 | E44: =E24*'Synergies (Bottom-Up Estimate)'!$B$44
B45: Year 2 Synergy Realized (Rs.M) | C45: =C24*'Synergies (Bottom-Up Estimate)'!$C$44 | D45: =D24*'Synergies (Bottom-Up Estimate)'!$C$44 | E45: =E24*'Synergies (Bottom-Up Estimate)'!$C$44
B46: PV of Year 1+2 Synergy (Rs.M) | C46: =C44/(1+C17)+C45/(1+C17)^2 | D46: =D44/(1+D17)+D45/(1+D17)^2 | E46: =E44/(1+E17)+E45/(1+E17)^2
B47: PV of Year 3+ Perpetuity, full run-rate (Rs.M) | C47: =(C24*(1+C25))/(C17-C25)/(1+C17)^2 | D47: =(D24*(1+D25))/(D17-D25)/(1+D17)^2 | E47: =(E24*(1+E25))/(E17-E25)/(1+E17)^2
B48: Total Synergy PV before integration cost (Rs.M) | C48: =C46+C47 | D48: =D46+D47 | E48: =E46+E47
B49: Less: One-Time Integration Cost (Rs.M, undiscounted, paid at close) | C49: =-'Synergies (Bottom-Up Estimate)'!$B$49 | D49: =-'Synergies (Bottom-Up Estimate)'!$B$49 | E49: =-'Synergies (Bottom-Up Estimate)'!$B$49
B50: Net Adjusted Synergy PV (Rs.M) | C50: =C48+C49 | D50: =D48+D49 | E50: =E48+E49
B51: Net Adjusted Synergy PV per Mindtree Share (Rs.) | C51: =C50*1000000/'Exchange Ratio & Ownership'!$C$12 | D51: =D50*1000000/'Exchange Ratio & Ownership'!$C$12 | E51: =E50*1000000/'Exchange Ratio & Ownership'!$C$12
A53: ## | B53: Exchange Ratio Bounds - Ramp + Integration-Cost Adjusted, vs. Original
C55: Bear | D55: Base | E55: Bull
B56: Min Exchange Ratio (Seller floor - unchanged, doesn't involve synergy) | C56: =C32 | D56: =D32 | E56: =E32
...

Sheet Football Field
A1: # | B1: Football Field - Valuation Synthesis
B2: Every Low/Median/High below is a live formula pulling from the DCF, Comps, and Precedent Transactions sheets already built and verified - this sheet adds no new numbers, just a synthesized view. The Event Study (CAR) isn't shown here - it measures market reaction, a return, not a value-per-share estimate, so it doesn't belong on this axis.
A4: ## | B4: LTI
B6: Method | C6: Low | D6: Median / Base | E6: High
B7: DCF (WACC +/-2pp) | C7: ='LTI_Sensitivity Tables'!E12 | D7: ='LTI_Sensitivity Tables'!E10 | E7: ='LTI_Sensitivity Tables'!E8
B8: Trading Comps (median-mean P/E) | C8: ='LTI_Comps'!B16 | D8: =('LTI_Comps'!B16+'LTI_Comps'!B17)/2 | E8: ='LTI_Comps'!B17
B9: Precedent Transactions (EV/Rev) | C9: ='Precedent Transactions'!C46 | D9: ='Precedent Transactions'!C39 | E9: ='Precedent Transactions'!C53
B10: Actual Market Price (6-May-2022) | D10: ='LTI_WACC Schedule'!C6
A13: ## | B13: Mindtree
B15: Method | C15: Low | D15: Median / Base | E15: High
B16: DCF (WACC +/-2pp) | C16: ='MT_Sensitivity Tables'!E12 | D16: ='MT_Sensitivity Tables'!E10 | E16: ='MT_Sensitivity Tables'!E8
B17: Trading Comps (median-mean P/E) | C17: ='MT_Comps'!B16 | D17: =('MT_Comps'!B16+'MT_Comps'!B17)/2 | E17: ='MT_Comps'!B17
B18: Precedent Transactions (EV/Rev) | C18: ='Precedent Transactions'!D46 | D18: ='Precedent Transactions'!D39 | E18: ='Precedent Transactions'!D53
B19: Actual Market Price (6-May-2022) | D19: ='MT_WACC Schedule'!C6
A22: ## | B22: Chart Helper Columns (base = Low, range = High-Low)
B24: Method | C24: Base (=Low) | D24: Range (=High-Low)
B25: =B7 | C25: =C7 | D25: =E7-C7
B26: =B8 | C26: =C8 | D26: =E8-C8
B27: =B9 | C27: =C9 | D27: =E9-C9
B29: =B16 | C29: =C16 | D29: =E16-C16
B30: =B17 | C30: =C17 | D30: =E17-C17
B31: =B18 | C31: =C18 | D31: =E18-C18

Sheet Precedent Transactions
A1: # | B1: Precedent Transactions Analysis
B2: Real, publicly disclosed Indian IT-services M&A transactions (sourced live via web search, citations in column I). Multiples the acquirer actually paid, applied to LTI's and Mindtree's own FY22 financials - a third, independent cross-check alongside the DCF and Trading Comps already built.
A4: ## | B4: Transaction Table
B6: Acquirer / Target | C6: Announced | D6: Deal Value (EV, $M) | E6: Target Revenue (LTM, $M) | F6: EV/Revenue | G6: Target EBITDA or EBIT (LTM, $M) | H6: EV/EBITDA or EV/EBIT
B7: Capgemini / iGate Corporation | C7: Apr-2015 | D7: 4000 | E7: 1300 | F7: =D7/E7 | G7: n/a | H7: n/a | I7: Deal value + FY2014 revenue: Capgemini press release, Forbes India, Business Standard (consultancy.uk, forbesindia.com) - deal explicitly described as "over 3x revenue", consistent with the 3.08x computed here. FY2014 EBITDA not cleanly found in two searches - left blank rather than estimated.
B8: Blackstone / Mphasis (from HPE) [EBITDA (range, not point)] | C8: Apr-2016 | D8: n/a | E8: n/a | F8: n/a | G8: n/a | H8: 9 | I8: Bloomberg (Blackstone to buy HPE's 60.5% stake for ~$825M, INR430/share; up to $1.1bn for control via open offer), Blackstone press release. EV/Revenue not used - the %-stake / per-share math needed to back into a clean 100% EV was not reliably resolvable from public sources. EV/EBITDA entered directly from the source's own reported trading-multiple context: "8-10x LTM EBITDA, vs peer average 12-14x" - midpoint 9.0x entered here, not a formula.
B9: HCL Technologies / Geometric Ltd | C9: Apr-2016 | D9: n/a | E9: n/a | F9: 1.6 | G9: n/a | H9: n/a | I9: DQIndia, M&A Critique, Business Standard: deal for Geometric's IT services business (Rs.1,300cr EV, Rs.801cr FY15 revenue) explicitly reported as "~1.6 times the turnover" and a 23x P/E multiple. 1.6x entered directly as reported, not as a formula off the Rs./$ figures shown for reference - the $ figures are rough conversions that would carry FX-date rounding error the source's own 1.6x doesn't have.
B10: Carlyle Group / Hexaware Technologies [EBIT (operating profit, not EBITDA)] | C10: Jun-2021 | D10: 3000 | E10: 845 | F10: =D10/E10 | G10: 152 | H10: =D10/G10 | I10: Private Equity Insights: Carlyle's winning $3bn offer for Hexaware from Baring PE Asia (Jun-2021). CY2020 revenue $845M, operating profit $152M, as reported. Operating profit here is EBIT, not EBITDA - this multiple is EV/EBIT and is NOT combined with the Mphasis EV/EBITDA figure above; kept in a separate column.
B12: Structural precedent (not in multiples table): KPIT Technologies / Birlasoft merger (announced Jan-2018, effective Jan-2019) - a genuine stock-for-stock MERGER, not a cash acquisition: swap ratio 22 KPIT shares : 9 Birlasoft shares, forming a combined ~$700M-revenue IT services entity (which then demerged into Engineering vs IT Services businesses). No clean "price paid" multiple exists for a merger-plus-demerger of this kind, but it confirms stock-swap mergers are an established, executed transaction structure in Indian IT services - directly relevant to validating the LTI-Mindtree deal's chosen structure. (Source: KPIT/Birlasoft investor disclosures, Motilal Oswal deal report, M&A Critique.)
A14: ## | B14: Summary Statistics - EV/Revenue
B15: 3 of 4 transactions have a clean EV/Revenue (Capgemini/iGate, HCL/Geometric, Carlyle/Hexaware); Blackstone/Mphasis is excluded from this statistic (only EV/EBITDA was cleanly sourceable for it) - MEDIAN/AVERAGE/MIN/MAX below skip its "n/a" cell automatically.
B17: Median | C17: =MEDIAN(F7:F10)
B18: Mean | C18: =AVERAGE(F7:F10)
B19: Min | C19: =MIN(F7:F10)
B20: Max | C20: =MAX(F7:F10)
A22: ## | B22: Applied to LTI and Mindtree (FY22 financials, deal-year LTM)
C24: LTI | D24: Mindtree
B25: Revenue (FY22, Rs.M) | C25: ='LTI_P&L Schedule'!H7 | D25: ='MT_P&L Schedule'!H7
B26: EBITDA (FY22, Rs.M) | C26: ='LTI_P&L Schedule'!H11 | D26: ='MT_P&L Schedule'!H11
B27: EBIT (FY22, Rs.M) | C27: ='LTI_P&L Schedule'!H14 | D27: ='MT_P&L Schedule'!H14
B28: Debt incl. leases (book value, Rs.M) | C28: ='LTI_WACC Schedule'!C34 | D28: ='MT_WACC Schedule'!C34
B29: Cash & Cash Equivalents (Rs.M) | C29: =IFERROR(INDEX(LTI_HS_CONSOLIDATED!I:I,MATCH("CashAndCashEquivalents",LTI_HS_CONSOLIDATED!$C:$C,0)),0) | D29: =IFERROR(INDEX(MT_HS_CONSOLIDATED!I:I,MATCH("CashAndCashEquivalents",MT_HS_CONSOLIDATED!$C:$C,0)),0)
B30: Shares Outstanding | C30: ='LTI_WACC Schedule'!C7 | D30: ='MT_WACC Schedule'!C7
B31: Market Price (6-May-2022, Rs.) | C31: ='LTI_WACC Schedule'!C6 | D31: ='MT_WACC Schedule'!C6
B33: Net Debt (Rs.M) | C33: =C28-C29 | D33: =D28-D29
A35: ### | B35: Method A: EV/Revenue @ Median
B36: Implied EV (Rs.M) | C36: =C25*$C$17 | D36: =D25*$C$17
B37: Less: Net Debt (Rs.M) | C37: =-C33 | D37: =-D33
B38: Implied Equity Value (Rs.M) | C38: =C36+C37 | D38: =D36+D37
B39: Implied Value / Share (Rs.) | C39: =C38/C30 | D39: =D38/D30
B40: % of Actual Market Price | C40: =C39/C31 | D40: =D39/D31
A42: ### | B42: Method A-Low: EV/Revenue @ Min
B43: Implied EV (Rs.M) | C43: =C25*$C$19 | D43: =D25*$C$19
B44: Less: Net Debt (Rs.M) | C44: =-C33 | D44: =-D33
B45: Implied Equity Value (Rs.M) | C45: =C43+C44 | D45: =D43+D44
B46: Implied Value / Share (Rs.) | C46: =C45/C30 | D46: =D45/D30
B47: % of Actual Market Price | C47: =C46/C31 | D47: =D46/D31
A49: ### | B49: Method A-High: EV/Revenue @ Max
B50: Implied EV (Rs.M) | C50: =C25*$C$20 | D50: =D25*$C$20
B51: Less: Net Debt (Rs.M) | C51: =-C33 | D51: =-D33
...

Sheet Best Owner Analysis
A1: # | B1: Best Owner Analysis (audit gap #1)
B2: Standard 'Best Owner' test (McKinsey & Co. / Copeland-Koller Valuation textbook - CONFIRMED via live notebook query, 25-Aug-2026, after NotebookLM auth was restored; an earlier version of this sheet used 5 self-derived levers instead of the real ones below - corrected here, not silently). Tests whether LTI specifically extracts more value from Mindtree's assets than any other plausible owner would, across the 5 REAL value levers - deliberately harder than the deal announcement's own 'highly complementary strengths' language, which doesn't by itself distinguish LTI from a hypothetical alternative acquirer.
A4: ## | B4: What the deal announcement actually said (for contrast)
B5: A.M. Naik (L&T Group Chairman): "The highly complementary strengths of LTI and Mindtree make this integration a win-win proposition..." - S.N. Subrahmanyan: "...turning the collective wisdom of the two companies into a much larger force..." Genuine statements, but generic - this kind of language appears in nearly every stock-for-stock merger announcement. Source: task1_rationale.json.
A7: ## | B7: Lever A: Unique Links with Other Businesses
B8: Delivery-center city overlap (of 10 India cities each) | C8: 7 of 10
B9: Subcontractor-cost pooling synergy (Rs.Mn/yr) | C9: ='Synergies (Bottom-Up Estimate)'!D9
B10: Real-estate consolidation synergy (Rs.Mn/yr) | C10: ='Synergies (Bottom-Up Estimate)'!D16
B11: LTI largest vertical: BFSI / Mindtree largest: CMT (18% BFSI) | C11: Complementary
B12: Cross-sell revenue synergy estimate (Rs.Mn/yr, illustrative) | C12: ='Synergies (Bottom-Up Estimate)'!D25
B13: Verdict | E13: The textbook's own example for this lever is exactly this shape: 'sharing existing manufacturing infrastructure' and 'established, highly specialized distribution networks and sales channels to cross-sell.' The 70% city overlap and complementary verticals are real, specific structural facts about these two companies (not true of an arbitrary IT-services pairing), and both cost-synergy categories are sized bottom-up from real cost bases. The revenue cross-sell number is this workbook's own weakest figure by its own admission (2% of revenue, 'included for completeness rather than confidence' - no deal-pipeline data exists to ground it further). Real and specific for cost links; directionally real but weakly sized for revenue links.
A15: ## | B15: Lever B: Distinctive Functional or Managerial Skills
B16: Combined workforce (approx.) | C16: ~90,000
B17: Verdict | E17: Per the textbook, this lever requires a distinctive skill that maps to the target's primary value driver - not just generic scale. Management's own language here is genuinely generic ('collective wisdom,' 'diversity of scale and capabilities'), with no specific disclosed mechanism (no named platform, methodology, or capability that flows specifically from LTI to Mindtree or vice versa, the way subcontractor pooling or city overlap are concrete). Unverifiable with available public data - reported as such, not assumed true or false.
A19: ## | B19: Lever C: Better Governance and Incentives
B20: L&T Group Chairman, pre- AND post-merger | C20: A.M. Naik (both)
B21: Verdict | E21: Doesn't apply, and that itself is the finding. This lever tests whether a NEW owner brings better capital-allocation discipline than the target had standalone (the textbook's own examples: lean corporate centers, high-powered incentive design replacing weaker incumbent governance). LTI and Mindtree were both L&T Group subsidiaries with the SAME ultimate parent and SAME Group Chairman before this deal - governance discipline isn't something the merger newly introduces, since both companies already answered to it. Close to moot for a merger-of-affiliates structure.
A23: ## | B23: Lever D: Better Insight or Foresight
B24: Verdict | E24: No public evidence either way. This lever requires proprietary, superior market foresight that lets the owner make bold, early resource-allocation calls ahead of the market. Nothing in either company's public disclosures speaks to this directly (no documented instance of L&T Group correctly anticipating an IT-services market shift years ahead of peers and acting on it via this merger). Genuinely unverifiable with available data, not a lever this analysis can test one way or the other.
A27: ## | B27: Lever E: Clout / Influence over Critical Stakeholders
B28: Combined entity market-cap rank (India IT services) | C28: 5th largest
B29: Verdict | E29: Likely LOW relevance here, and the textbook itself flags why: this lever matters most in heavily regulated, capital-intensive sectors and developing capital markets - not a competitive, globally-traded IT-services business, where (per the same source) 'clout with the government rarely provides an advantage' in developed markets. The one plausible channel - L&T Group's scale/reputation helping win larger enterprise RFPs that require vendor scale and financial stability - is consistent with the deal's own stated 'entered the elite league of top-tiered IT services companies' framing, but is a scale effect, not the specific stakeholder-clout mechanism (government, regulators) the textbook describes. Weak evidence, not strong.
A31: ## | B31: Important Context - Not One of the 5 Levers
B32: L&T's ownership of combined entity (actual, disclosed) | C32: ='Exchange Ratio & Ownership'!C19
B33: This deal's premium/(discount) to Mindtree's standalone price | C33: ='Precedent Transactions'!C100 | E33: L&T retained 68.73% of the combined entity - both companies were, and remain, part of the same corporate family. Combined with the near-zero deal premium, this explains WHY the Best-Owner framework doesn't map cleanly onto this specific deal: there was no competitive process, because there was really only one plausible owner (the L&T Group, which already owned both) - a structural fact about THIS deal, correctly kept separate from the 5 levers themselves rather than mislabeled as a 6th lever.
A36: ## | B36: Overall Conclusion
B37: Of the 5 real Best-Owner levers: A (Unique Links) is real and well-evidenced on the cost side, weaker on the revenue side. B (Distinctive Skills) and D (Insight/Foresight) are unverifiable with available public data - reported honestly as untestable, not assumed. C (Governance) doesn't apply because both companies already shared L&T governance pre-merger. E (Stakeholder Clout) is plausible but weak, and the textbook's own caveats suggest it matters less in this kind of market. Combined with the fact that L&T already owned both companies (Important Context above), the honest overall read is that this deal creates real, specific, but modest value primarily through Lever A (cost/revenue links), not through a genuine multi-lever best-owner advantage over alternative owners - because there effectively weren't competing alternative owners to test against.

Sheet Goal-Seek Synergy Backsolve
A1: # | B1: Goal-Seek Synergy Backsolve (audit gap #2) | D1: CONFIRMED via live notebook query, 25-Aug-2026 (auth restored): real IB technique sets NPV of synergies = acquisition premium + fees, backsolves the constant annual run-rate via Excel Goal Seek (Bruner's textbook worked example: $142M/yr on a $1bn premium, discounted at 6% cost of debt for low-risk cost synergies). Closed-form algebraic solve here is the exact equivalent for this linear structure. LIMITATION now confirmed, not just guessed: a fully rigorous treatment discounts cost synergies at the acquirer's pre-tax cost of debt and revenue synergies at cost of equity separately (different risk profiles) - this sheet uses a single blended acquirer WACC for the whole backsolved figure, a real simplification, not the textbook-precise method.
A3: ## | B3: Scenario A: vs. Market Price Basis (what was actually paid, in market terms)
B4: Value Received per Mindtree Share (Rs.) | C4: ='Exchange Ratio & Ownership'!C29
B5: Mindtree Standalone Market Price, 6-May-2022 (Rs.) | C5: ='Exchange Ratio & Ownership'!C30
B6: Mindtree Shares Outstanding | C6: ='MT_WACC Schedule'!C7
B7: Deal Value Paid (Rs.M) | C7: =C4*C6/1000000
B8: Mindtree Standalone Market Value (Rs.M) | C8: =C5*C6/1000000
B9: Excess Paid over Market Value (Rs.M) | C9: =C7-C8 | D9: Matches the -0.64% discount already found in Precedent Transactions/Exchange Ratio & Ownership - the deal was priced AT (very slightly below) market, so on a pure market-price basis, essentially no premium needs synergy justification at all.
A11: ## | B11: Scenario B: vs. DCF Intrinsic Value Basis (what the model says Mindtree is really worth)
B12: Mindtree DCF Equity Value (Rs.M) | C12: =MT_DCF!C32/1000000
B13: Excess Paid over DCF Intrinsic Value (Rs.M) | C13: =C7-C12
B14: Estimated Deal Fees (Rs.M) - generic 1% of deal value (not disclosed; standard IB rule-of-thumb, low end since this is an affiliate merger, not a competitively-shopped acquisition) | C14: =C7*0.01
B15: Total Value Requiring Synergy Justification (Rs.M) | C15: =C13+C14
B17: Discount Rates by Synergy Risk Type (differentiated per synergy risk - confirmed via notebook)
B18: Pre-Tax Cost of Debt (for cost synergies - low risk, EBIT-like volatility) | C18: ='LTI_WACC Schedule'!C30
B19: Cost of Equity (for revenue synergies - high risk, speculative) | C19: ='LTI_WACC Schedule'!C23
B20: Terminal Growth Rate (locked-in, both companies) | C20: ='LTI_DCF'!C22
A21: ##
B22: Bookend Backsolves (the Rs.130,318M gap could be closed via cost savings, revenue synergies, or a mix - both pure cases shown as bookends)
B23: If closed ENTIRELY via cost synergies, discounted at cost of debt (Rs.M/yr) | C23: =C15*(C18-C20)
B24: If closed ENTIRELY via revenue synergies, discounted at cost of equity (Rs.M/yr) | C24: =C15*(C19-C20)
B25: For reference: single blended-WACC method (original version of this sheet, Rs.M/yr) | C25: =C15*('LTI_WACC Schedule'!C39-C20)
B27: Sanity Check vs. This Model's Own Bottom-Up Estimate, Split by Type
B28: Bottom-up COST synergy estimate (subcontractor+real estate, Rs.M/yr) | C28: ='Synergies (Bottom-Up Estimate)'!D9+'Synergies (Bottom-Up Estimate)'!D16
B29: Bottom-up REVENUE synergy estimate (cross-sell, Rs.M/yr) | C29: ='Synergies (Bottom-Up Estimate)'!D25
B30: Cost-backsolve (row 23) as multiple of bottom-up COST estimate | C30: =C23/C28
B31: Revenue-backsolve (row 24) as multiple of bottom-up REVENUE estimate | C31: =C24/C29
B33: Reading this: | D33: Tightened 25-Aug-2026 after notebook confirmation of the differentiated-rate technique. If the Rs.130,318M DCF-basis gap had to be closed ENTIRELY via cost synergies (discounted at the lower, less-risky pre-tax cost of debt), the required run-rate is Rs.2,955M/yr - only 0.61x of this workbook's own bottom-up COST estimate (Rs.4,884M/yr, subcontractor+real-estate) - comfortably covered. If closed ENTIRELY via revenue synergies (discounted at the higher cost of equity, reflecting real execution risk), the required run-rate is Rs.6,639M/yr - 1.27x of the bottom-up REVENUE estimate (Rs.5,239M/yr, cross-sell) - i.e. relying purely on revenue synergies would need MORE than even this workbook's own already-uncertain cross-sell estimate. Sharper and more honest than the original single-blended-WACC figure (Rs.6,576M/yr, kept for reference): cost synergies alone can defend the deal; revenue synergies alone cannot, without exceeding the model's own most speculative number. Consistent with, and now quantifying, this session's repeated finding that the cost-side synergies are this model's more reliable value driver.

Sheet Value of Control
A1: # | B1: Value of Control (audit gap #3) | E1: Test-and-revert dated 25-Aug-2026, CORRECTED same day after NotebookLM auth was restored and the actual methodology was verified against the notebook: an earlier version of this sheet forced Mindtree's margin DOWN to the exact peer-median, violating Damodaran's own rule that value-of-control adjustments should never degrade a company already performing at or above the benchmark. Corrected below - not silently.
A3: ## | B3: Methodology
B4: Value of Control = Optimally-Managed Value minus Status-Quo Value. Optimally-Managed = same locked DCF structure, re-run with Employee Benefit % (the model's own margin driver) shifted from each company's own trending baseline to hit the industry-median EBIT margin (18.22%, FY24 peer-median from this workbook's own Comps sheet - Task 25's industry-adjusted correction), plus an illustrative 'optimal' 15% Target Debt/Capitalization (generic assumption, not independently derived - see the capital-structure finding below for why this particular lever turned out not to matter here).
A6: ## | C6: LTI | D6: Mindtree
B7: FY22 Actual EBIT Margin | C7: 0.1726 | D7: 0.1856
B8: Industry-Median EBIT Margin (peer median, FY24) | C8: 0.1822 | D8: 0.1822
B9: Gap to Close | C9: =C8-C7 | D9: =D8-D7 | E9: LTI sits BELOW the peer median (room to improve). Mindtree sits ABOVE it - per Damodaran's own framework ('value of control is negligible for firms operating at or close to their optimal value'), the correct treatment for an already-above-benchmark company is NOT to force its margin down to the median. Corrected from an earlier version of this sheet that did exactly that.
B11: Status-Quo Value / Share (Rs., locked-in baseline) | C11: =LTI_DCF!C33 | D11: =MT_DCF!C33
B12: Optimally-Managed Value / Share (Rs.) - LTI: test result, hardcoded (see note). Mindtree: = Status-Quo (no change - already above peer median, see correction note) | C12: 3851.63 | D12: =D11
B13: Value of Control (Rs./share) | C13: =C12-C11 | D13: =D12-D11
B14: Value of Control (%) | C14: =C13/C11 | D14: =D13/D11
A16: ## | B16: Capital-Structure Lever - a real finding, not a result
B17: The 15% Target Debt/Capitalization override was applied to both companies' 'INPUT: Target Debt/Capitalization Ratio' cell during this test, but produced ZERO change to either company's WACC - confirmed by direct inspection of 'LTI_WACC Schedule'!C14 (This company's D/E), which references 'Inputs & Assumptions'!C66 (the historically-derived 'Suggested' value) and NOT C67 (the INPUT override cell actually being tested). C67 does flow into the Debt Schedule's forecast debt level ('LTI_Schedules'!I92), so it isn't dead - it just isn't wired into the discount-rate side of the model at all. This means the WACC used for the Optimally-Managed test above is identical to the Status-Quo WACC (10.06% LTI, 10.04% MT) - the entire Value of Control result above comes from the margin lever alone, not a genuine 'optimal capital structure' effect. Flagged plainly as a real gap in the underlying tool, not smoothed over or silently worked around.
A20: ## | B20: Reading This
B21: CORRECTED 25-Aug-2026 after notebook re-verification (see header note). LTI's Value of Control is small and positive (Rs.3,845.72 -> Rs.3,851.63, +0.15%) - modest headroom from closing a real but small (0.97pp) below-median margin gap, tested via the sanctioned test-and-revert method. Mindtree's Value of Control is correctly ~0 (negligible) - Mindtree already runs ABOVE the peer-median EBIT margin (18.56% vs 18.22%), so per Damodaran's own framework no restructuring toward the median is warranted; an earlier version of this sheet incorrectly forced Mindtree's margin down to the median anyway and reported a spurious -13.5% Value of Control, which has been corrected here rather than left standing. The real, honest finding: this framework properly identifies asymmetric headroom - LTI has a little room to improve toward peer-typical performance, Mindtree is already performing at (or above) that bar and gains nothing from being forced toward it. A stricter test against a true best-in-class benchmark (e.g. TCS's 25.27% FY22 EBIT margin, the top of this workbook's own peer set, rather than the median) was not performed this session and would be the natural next refinement if a tighter optimal bar is wanted for Mindtree specifically.

Sheet AVP - Various Exchange Ratios
A1: # | B1: Analysis at Various (Exchange Ratio) Prices (audit gap #7) | J1: All-stock deal, so the AVP axis is the exchange ratio, not a dollar offer price. Pro forma PAT uses ACTUAL disclosed combined results, same convention as Pro Forma & Accretion-Dilution's Method A/B - a hypothetical ratio changes dilution, not real combined earnings power.
A4: ## | B4: Exchange Ratio Scenarios
B6: Exchange Ratio | C6: 0.6 | D6: 0.65 | E6: 0.68 | F6: 0.7 | G6: 0.73 | H6: 0.75 | I6: 0.8 | K6: 0.85 | L6: 0.9
G7: ACTUAL
B9: New LTI Shares Issued | C9: =C6*'Exchange Ratio & Ownership'!$C$12 | D9: =D6*'Exchange Ratio & Ownership'!$C$12 | E9: =E6*'Exchange Ratio & Ownership'!$C$12 | F9: =F6*'Exchange Ratio & Ownership'!$C$12 | G9: =G6*'Exchange Ratio & Ownership'!$C$12 | H9: =H6*'Exchange Ratio & Ownership'!$C$12 | I9: =I6*'Exchange Ratio & Ownership'!$C$12 | K9: =K6*'Exchange Ratio & Ownership'!$C$12 | L9: =L6*'Exchange Ratio & Ownership'!$C$12
B10: Pro Forma LTI Shares Outstanding | C10: =C9+'Exchange Ratio & Ownership'!$C$11 | D10: =D9+'Exchange Ratio & Ownership'!$C$11 | E10: =E9+'Exchange Ratio & Ownership'!$C$11 | F10: =F9+'Exchange Ratio & Ownership'!$C$11 | G10: =G9+'Exchange Ratio & Ownership'!$C$11 | H10: =H9+'Exchange Ratio & Ownership'!$C$11 | I10: =I9+'Exchange Ratio & Ownership'!$C$11 | K10: =K9+'Exchange Ratio & Ownership'!$C$11 | L10: =L9+'Exchange Ratio & Ownership'!$C$11
B11: Mindtree Ownership % of Combined | C11: =C9/C10 | D11: =D9/D10 | E11: =E9/E10 | F11: =F9/F10 | G11: =G9/G10 | H11: =H9/H10 | I11: =I9/I10 | K11: =K9/K10 | L11: =L9/L10
B13: Value Received per Mindtree Share (Rs.) | C13: =C6*'Exchange Ratio & Ownership'!$C$28 | D13: =D6*'Exchange Ratio & Ownership'!$C$28 | E13: =E6*'Exchange Ratio & Ownership'!$C$28 | F13: =F6*'Exchange Ratio & Ownership'!$C$28 | G13: =G6*'Exchange Ratio & Ownership'!$C$28 | H13: =H6*'Exchange Ratio & Ownership'!$C$28 | I13: =I6*'Exchange Ratio & Ownership'!$C$28 | K13: =K6*'Exchange Ratio & Ownership'!$C$28 | L13: =L6*'Exchange Ratio & Ownership'!$C$28
B14: Premium / (Discount) to MT Market Price | C14: =C13/'Exchange Ratio & Ownership'!$C$30-1 | D14: =D13/'Exchange Ratio & Ownership'!$C$30-1 | E14: =E13/'Exchange Ratio & Ownership'!$C$30-1 | F14: =F13/'Exchange Ratio & Ownership'!$C$30-1 | G14: =G13/'Exchange Ratio & Ownership'!$C$30-1 | H14: =H13/'Exchange Ratio & Ownership'!$C$30-1 | I14: =I13/'Exchange Ratio & Ownership'!$C$30-1 | K14: =K13/'Exchange Ratio & Ownership'!$C$30-1 | L14: =L13/'Exchange Ratio & Ownership'!$C$30-1
B16: Pro Forma EPS - FY22 basis (Rs.) | C16: ='Pro Forma & Accretion-Dilution'!$C$18*1000000/C10 | D16: ='Pro Forma & Accretion-Dilution'!$C$18*1000000/D10 | E16: ='Pro Forma & Accretion-Dilution'!$C$18*1000000/E10 | F16: ='Pro Forma & Accretion-Dilution'!$C$18*1000000/F10 | G16: ='Pro Forma & Accretion-Dilution'!$C$18*1000000/G10 | H16: ='Pro Forma & Accretion-Dilution'!$C$18*1000000/H10 | I16: ='Pro Forma & Accretion-Dilution'!$C$18*1000000/I10 | K16: ='Pro Forma & Accretion-Dilution'!$C$18*1000000/K10 | L16: ='Pro Forma & Accretion-Dilution'!$C$18*1000000/L10
B17: Accretion / (Dilution) vs. LTI Standalone EPS - FY22 basis | C17: =C16/'Pro Forma & Accretion-Dilution'!$C$72-1 | D17: =D16/'Pro Forma & Accretion-Dilution'!$C$72-1 | E17: =E16/'Pro Forma & Accretion-Dilution'!$C$72-1 | F17: =F16/'Pro Forma & Accretion-Dilution'!$C$72-1 | G17: =G16/'Pro Forma & Accretion-Dilution'!$C$72-1 | H17: =H16/'Pro Forma & Accretion-Dilution'!$C$72-1 | I17: =I16/'Pro Forma & Accretion-Dilution'!$C$72-1 | K17: =K16/'Pro Forma & Accretion-Dilution'!$C$72-1 | L17: =L16/'Pro Forma & Accretion-Dilution'!$C$72-1
B19: Pro Forma EPS - FY23 actual basis (Rs.) | C19: ='Pro Forma & Accretion-Dilution'!$D$18*1000000/C10 | D19: ='Pro Forma & Accretion-Dilution'!$D$18*1000000/D10 | E19: ='Pro Forma & Accretion-Dilution'!$D$18*1000000/E10 | F19: ='Pro Forma & Accretion-Dilution'!$D$18*1000000/F10 | G19: ='Pro Forma & Accretion-Dilution'!$D$18*1000000/G10 | H19: ='Pro Forma & Accretion-Dilution'!$D$18*1000000/H10 | I19: ='Pro Forma & Accretion-Dilution'!$D$18*1000000/I10 | K19: ='Pro Forma & Accretion-Dilution'!$D$18*1000000/K10 | L19: ='Pro Forma & Accretion-Dilution'!$D$18*1000000/L10
B20: Accretion / (Dilution) vs. LTI Standalone EPS - FY23 basis | C20: =C19/'Pro Forma & Accretion-Dilution'!$C$72-1 | D20: =D19/'Pro Forma & Accretion-Dilution'!$C$72-1 | E20: =E19/'Pro Forma & Accretion-Dilution'!$C$72-1 | F20: =F19/'Pro Forma & Accretion-Dilution'!$C$72-1 | G20: =G19/'Pro Forma & Accretion-Dilution'!$C$72-1 | H20: =H19/'Pro Forma & Accretion-Dilution'!$C$72-1 | I20: =I19/'Pro Forma & Accretion-Dilution'!$C$72-1 | K20: =K19/'Pro Forma & Accretion-Dilution'!$C$72-1 | L20: =L19/'Pro Forma & Accretion-Dilution'!$C$72-1
J27: Reading this:
J28: Clean, monotonic trade-off curve, as expected mechanically: a lower ratio pays Mindtree shareholders less (bigger discount to their own market price - -18.3% at 0.60x vs the actual -0.64% at 0.73x) but dilutes LTI's existing shareholders less (more accretive, +9.86% at 0.60x on an FY22 basis vs +1.90% at the actual ratio); a higher ratio does the reverse (+22.5% premium at 0.90x, but turns mildly DILUTIVE on an FY22 basis by around 0.75-0.80x, and stays accretive throughout on the more favorable FY23-actual-PAT basis even at 0.90x). The actual 0.73 ratio sits close to the low-premium end of this range, not the middle or high end - consistent with, and now a third independent confirmation of, the 'merger of affiliates priced near market, not a competitive buyout' finding already established in Precedent Transactions, Exchange Ratio & Ownership, and Goal-Seek Synergy Backsolve. A buyer optimizing purely for EPS accretion would have pushed for a lower ratio than 0.73; the fact that it wasn't pushed lower is itself consistent with this being a relative-value settlement between affiliated companies rather than an adversarial negotiation.

Sheet Reference LBO Floor
A1: # | B1: Reference LBO Floor Analysis (audit gap #9) | I1: CONFIRMED via live notebook query, 25-Aug-2026 (auth restored): real technique matches - max sponsor price at a 15-20% IRR hurdle (20-25%+ for riskier targets) sets a market-clearing floor for strategic buyers; exit multiple <= entry multiple is standard (no expansion assumed, as done here); LBO valuation is 'traditionally toward the lower end' of the valuation hierarchy - exactly what this sheet finds. Leverage here (3.5x) sits within the confirmed real range (3-6x EBITDA, senior debt typically 60-70% of purchase price). One simplification now explicitly confirmed rather than assumed: the real technique models a full 100% cash-sweep debt paydown waterfall (mandatory amortization, then optional prepayment); this sheet holds debt flat across the hold, a deliberately conservative simplification that only understates the resulting IRR/floor, confirmed - not guessed - to be conservative relative to the real technique.
A4: ## | B4: LTI Standalone
B6: Entry EBITDA - FY22 actual (Rs.M) | C6: ='LTI_P&L Schedule'!H11/1000000
B7: Exit EBITDA - FY2027E, 5-year forecast (Rs.M) | C7: ='LTI_P&L Schedule'!M11/1000000
B8: Implied 5-yr EBITDA CAGR | C8: =(C7/C6)^(1/5)-1
B9: Assumed Leverage (Debt/EBITDA) - generic IT-services LBO convention | C9: 3.5
B10: Debt Raised (Rs.M) - entry level, before cash-sweep paydown (see schedule below) | C10: =C9*C6
B11: Target Sponsor IRR (5-yr hold) - generic PE benchmark | C11: 0.22
B13: Entry/Exit Multiple (no expansion assumed) | C13: 6 | D13: 7 | E13: 8 | F13: 9 | G13: 10 | H13: 11
F14: Blackstone/Mphasis actual
B15: Entry EV (Rs.M) | C15: =C13*$C$6 | D15: =D13*$C$6 | E15: =E13*$C$6 | F15: =F13*$C$6 | G15: =G13*$C$6 | H15: =H13*$C$6
B16: Entry Equity Check (Rs.M) | C16: =C15-$C$10 | D16: =D15-$C$10 | E16: =E15-$C$10 | F16: =F15-$C$10 | G16: =G15-$C$10 | H16: =H15-$C$10
