Workbook

Sheet Cover Page
B2: Suzlon Energy Limited
B3: NSE: SUZLON | Discounted Cash Flow Valuation
B4: Valuation date: 26-Sep-2025
B7: Key Outputs
B8: Implied Value / Share | C8: =DCF!C33 -> 56.048728
B9: Actual Market Price | C9: ='WACC Schedule'!$C6 -> 56.04
B10: WACC | C10: ='WACC Schedule'!$C39 -> 0.078867218
B11: Terminal Growth Rate | C11: =DCF!C22 -> 0.0501
B12: Explicit Forecast Horizon | C12: ="10 years ("&DCF!C5&"-"&DCF!L5&")" -> 10 years (FY2026E-FY2035E)
B15: Contents
B16: Inputs & Assumptions
B17: HIST_CON
B18: HIST_STAND
B19: RATIO_ANALYSIS
B20: DUPONT_ANALYSIS
B21: Schedules
B22: WC_SCHEDULE
B23: P&L Schedule
B24: WACC Schedule
B25: DCF
B26: Sensitivity Tables
... B34: Academic valuation project -- not investment advice. Every figure on this page is a live formula referencing the schedules that follow; nothing here is a pasted value.

Sheet Inputs & Assumptions
A1: # | B1: Inputs & Assumptions -- forecast years only
B3: Driver | C3: FY? | D3: FY2017 | E3: FY2018 | F3: FY2019 | G3: FY2020 | H3: FY2021 | I3: FY2022 | J3: FY2023 | K3: FY2024 | L3: FY2025 | M3: FY2026E | N3: FY2027E | O3: FY2028E | P3: FY2029E | Q3: FY2030E | R3: FY2031E | S3: FY2032E | T3: FY2033E | U3: FY2034E | V3: FY2035E
A5: # | B5: Outlier Filter -- excludes statistically anomalous years (IQR fence on YoY growth) from the Terminal Growth Rate and PP&E Additions Growth trend regressions
B7: Suggested: Outlier Filter Enabled (1=on, 0=off) -- default 1 (>=5yr history, enough points for a meaningful IQR fence) | C7: 1
B8: INPUT: Outlier Filter Enabled (1=on, 0=off)
A10: # | B10: Terminal / Fade-Target Growth Rate (computed from this company's own full history)
B12: Suggested: Terminal Growth Rate -- MIN(this company's own full-history log-linear trend on Total Revenue, with statistically anomalous years excluded per the Outlier Filter above, the Risk-Free Rate). No company grows faster than the risk-free rate forever -- caps a fast-growing company's own historical trend (seen on AdaniPorts: ~16.5%/yr, which broke the Value-Driver TV formula outright) without hardcoding an external macro number; slow-growth companies (e.g. Suzlon, ~0.75%/yr) are unaffected since their own trend already sits below the cap. | C12: =MIN(SLOPE(Schedules!C18:L18,Schedules!C12:L12),'WACC Schedule'!$C$21) -> 0.047222046 | D12: =$C$12 -> 0.047222046 | E12: =$C$12 -> 0.047222046 | F12: =$C$12 -> 0.047222046 | G12: =$C$12 -> 0.047222046 | H12: =$C$12 -> 0.047222046 | I12: =$C$12 -> 0.047222046 | J12: =$C$12 -> 0.047222046 | K12: =$C$12 -> 0.047222046 | L12: =$C$12 -> 0.047222046
B13: INPUT: Terminal Growth Rate (used by the fade) | C13: 0.0501
B15: Suggested: Growth Fade Half-Life, years -- default 6yr | C15: 6
B16: INPUT: Growth Fade Half-Life, years
B18: Suggested: Products Revenue Growth % -- log-linear, last 3yr, half-life decay to terminal | C18: =IFERROR(IF('Inputs & Assumptions'!$C$13="",'Inputs & Assumptions'!$C$12,'Inputs & Assumptions'!$C$13)+(IF('Inputs & Assumptions'!$C$19="",SLOPE(Schedules!J13:L13,Schedules!J12:L12),'Inputs & Assumptions'!$C$19)-(IF('Inputs & Assumptions'!$C$13="",'Inputs & Assumptions'!$C$12,'Inputs & Assumptions'!$C$13)))*0.5^(1/(IF('Inputs & Assumptions'!$C$16="",'Inputs & Assumptions'!$C$15,'Inputs & Assumptions'!$C$16))),IF('Inputs & Assumptions'!$C$13="",'Inputs & Assumptions'!$C$12,'Inputs & Assumptions'!$C$13)) -> 0.33402942 | D18: =IFERROR(IF('Inputs & Assumptions'!$C$13="",'Inputs & Assumptions'!$C$12,'Inputs & Assumptions'!$C$13)+(IF('Inputs & Assumptions'!$C$19="",SLOPE(Schedules!J13:L13,Schedules!J12:L12),'Inputs & Assumptions'!$C$19)-(IF('Inputs & Assumptions'!$C$13="",'Inputs & Assumptions'!$C$12,'Inputs & Assumptions'!$C$13)))*0.5^(2/(IF('Inputs & Assumptions'!$C$16="",'Inputs & Assumptions'!$C$15,'Inputs & Assumptions'!$C$16))),IF('Inputs & Assumptions'!$C$13="",'Inputs & Assumptions'!$C$12,'Inputs & Assumptions'!$C$13)) -> 0.30305236 | E18: =IFERROR(IF('Inputs & Assumptions'!$C$13="",'Inputs & Assumptions'!$C$12,'Inputs & Assumptions'!$C$13)+(IF('Inputs & Assumptions'!$C$19="",SLOPE(Schedules!J13:L13,Schedules!J12:L12),'Inputs & Assumptions'!$C$19)-(IF('Inputs & Assumptions'!$C$13="",'Inputs & Assumptions'!$C$12,'Inputs & Assumptions'!$C$13)))*0.5^(3/(IF('Inputs & Assumptions'!$C$16="",'Inputs & Assumptions'!$C$15,'Inputs & Assumptions'!$C$16))),IF('Inputs & Assumptions'!$C$13="",'Inputs & Assumptions'!$C$12,'Inputs & Assumptions'!$C$13)) -> 0.27545493 | F18: =IFERROR(IF('Inputs & Assumptions'!$C$13="",'Inputs & Assumptions'!$C$12,'Inputs & Assumptions'!$C$13)+(IF('Inputs & Assumptions'!$C$19="",SLOPE(Schedules!J13:L13,Schedules!J12:L12),'Inputs & Assumptions'!$C$19)-(IF('Inputs & Assumptions'!$C$13="",'Inputs & Assumptions'!$C$12,'Inputs & Assumptions'!$C$13)))*0.5^(4/(IF('Inputs & Assumptions'!$C$16="",'Inputs & Assumptions'!$C$15,'Inputs & Assumptions'!$C$16))),IF('Inputs & Assumptions'!$C$13="",'Inputs & Assumptions'!$C$12,'Inputs & Assumptions'!$C$13)) -> 0.25086842 | G18: =IFERROR(IF('Inputs & Assumptions'!$C$13="",'Inputs & Assumptions'!$C$12,'Inputs & Assumptions'!$C$13)+(IF('Inputs & Assumptions'!$C$19="",SLOPE(Schedules!J13:L13,Schedules!J12:L12),'Inputs & Assumptions'!$C$19)-(IF('Inputs & Assumptions'!$C$13="",'Inputs & Assumptions'!$C$12,'Inputs & Assumptions'!$C$13)))*0.5^(5/(IF('Inputs & Assumptions'!$C$16="",'Inputs & Assumptions'!$C$15,'Inputs & Assumptions'!$C$16))),IF('Inputs & Assumptions'!$C$13="",'Inputs & Assumptions'!$C$12,'Inputs & Assumptions'!$C$13)) -> 0.22896433 | H18: =IFERROR(IF('Inputs & Assumptions'!$C$13="",'Inputs & Assumptions'!$C$12,'Inputs & Assumptions'!$C$13)+(IF('Inputs & Assumptions'!$C$19="",SLOPE(Schedules!J13:L13,Schedules!J12:L12),'Inputs & Assumptions'!$C$19)-(IF('Inputs & Assumptions'!$C$13="",'Inputs & Assumptions'!$C$12,'Inputs & Assumptions'!$C$13)))*0.5^(6/(IF('Inputs & Assumptions'!$C$16="",'Inputs & Assumptions'!$C$15,'Inputs & Assumptions'!$C$16))),IF('Inputs & Assumptions'!$C$13="",'Inputs & Assumptions'!$C$12,'Inputs & Assumptions'!$C$13)) -> 0.20945 | I18: =IFERROR(IF('Inputs & Assumptions'!$C$13="",'Inputs & Assumptions'!$C$12,'Inputs & Assumptions'!$C$13)+(IF('Inputs & Assumptions'!$C$19="",SLOPE(Schedules!J13:L13,Schedules!J12:L12),'Inputs & Assumptions'!$C$19)-(IF('Inputs & Assumptions'!$C$13="",'Inputs & Assumptions'!$C$12,'Inputs & Assumptions'!$C$13)))*0.5^(7/(IF('Inputs & Assumptions'!$C$16="",'Inputs & Assumptions'!$C$15,'Inputs & Assumptions'!$C$16))),IF('Inputs & Assumptions'!$C$13="",'Inputs & Assumptions'!$C$12,'Inputs & Assumptions'!$C$13)) -> 0.19206471 | J18: =IFERROR(IF('Inputs & Assumptions'!$C$13="",'Inputs & Assumptions'!$C$12,'Inputs & Assumptions'!$C$13)+(IF('Inputs & Assumptions'!$C$19="",SLOPE(Schedules!J13:L13,Schedules!J12:L12),'Inputs & Assumptions'!$C$19)-(IF('Inputs & Assumptions'!$C$13="",'Inputs & Assumptions'!$C$12,'Inputs & Assumptions'!$C$13)))*0.5^(8/(IF('Inputs & Assumptions'!$C$16="",'Inputs & Assumptions'!$C$15,'Inputs & Assumptions'!$C$16))),IF('Inputs & Assumptions'!$C$13="",'Inputs & Assumptions'!$C$12,'Inputs & Assumptions'!$C$13)) -> 0.17657618 | K18: =IFERROR(IF('Inputs & Assumptions'!$C$13="",'Inputs & Assumptions'!$C$12,'Inputs & Assumptions'!$C$13)+(IF('Inputs & Assumptions'!$C$19="",SLOPE(Schedules!J13:L13,Schedules!J12:L12),'Inputs & Assumptions'!$C$19)-(IF('Inputs & Assumptions'!$C$13="",'Inputs & Assumptions'!$C$12,'Inputs & Assumptions'!$C$13)))*0.5^(9/(IF('Inputs & Assumptions'!$C$16="",'Inputs & Assumptions'!$C$15,'Inputs & Assumptions'!$C$16))),IF('Inputs & Assumptions'!$C$13="",'Inputs & Assumptions'!$C$12,'Inputs & Assumptions'!$C$13)) -> 0.16277747 | L18: =IFERROR(IF('Inputs & Assumptions'!$C$13="",'Inputs & Assumptions'!$C$12,'Inputs & Assumptions'!$C$13)+(IF('Inputs & Assumptions'!$C$19="",SLOPE(Schedules!J13:L13,Schedules!J12:L12),'Inputs & Assumptions'!$C$19)-(IF('Inputs & Assumptions'!$C$13="",'Inputs & Assumptions'!$C$12,'Inputs & Assumptions'!$C$13)))*0.5^(10/(IF('Inputs & Assumptions'!$C$16="",'Inputs & Assumptions'!$C$15,'Inputs & Assumptions'!$C$16))),IF('Inputs & Assumptions'!$C$13="",'Inputs & Assumptions'!$C$12,'Inputs & Assumptions'!$C$13)) -> 0.15048421
B19: INPUT: Products Revenue Growth % (overrides the trend/fade) | C19: 0.3688
A21: # | B21: Misc. Revenue / WC Schedule Drivers
B23: Suggested: Misc. Other Operating Revenue % of Total Revenue, last 3yr avg | C23: =AVERAGE(Schedules!J24:L24) -> 0.0041451154 | D23: =$C$23 -> 0.0041451154 | E23: =$C$23 -> 0.0041451154 | F23: =$C$23 -> 0.0041451154 | G23: =$C$23 -> 0.0041451154 | H23: =$C$23 -> 0.0041451154 | I23: =$C$23 -> 0.0041451154 | J23: =$C$23 -> 0.0041451154 | K23: =$C$23 -> 0.0041451154 | L23: =$C$23 -> 0.0041451154
B24: INPUT: Misc. Other Operating Revenue % of Total Revenue
B26: Suggested: Services Revenue Growth % -- log-linear, last 3yr, half-life decay to terminal (simplified vs. an installed-base driver) | C26: =IFERROR(IF('Inputs & Assumptions'!$C$13="",'Inputs & Assumptions'!$C$12,'Inputs & Assumptions'!$C$13)+(IF('Inputs & Assumptions'!$C$27="",SLOPE(Schedules!J25:L25,Schedules!J12:L12),'Inputs & Assumptions'!$C$27)-(IF('Inputs & Assumptions'!$C$13="",'Inputs & Assumptions'!$C$12,'Inputs & Assumptions'!$C$13)))*0.5^(1/(IF('Inputs & Assumptions'!$C$16="",'Inputs & Assumptions'!$C$15,'Inputs & Assumptions'!$C$16))),IF('Inputs & Assumptions'!$C$13="",'Inputs & Assumptions'!$C$12,'Inputs & Assumptions'!$C$13)) -> 0.33402942 | D26: =IFERROR(IF('Inputs & Assumptions'!$C$13="",'Inputs & Assumptions'!$C$12,'Inputs & Assumptions'!$C$13)+(IF('Inputs & Assumptions'!$C$27="",SLOPE(Schedules!J25:L25,Schedules!J12:L12),'Inputs & Assumptions'!$C$27)-(IF('Inputs & Assumptions'!$C$13="",'Inputs & Assumptions'!$C$12,'Inputs & Assumptions'!$C$13)))*0.5^(2/(IF('Inputs & Assumptions'!$C$16="",'Inputs & Assumptions'!$C$15,'Inputs & Assumptions'!$C$16))),IF('Inputs & Assumptions'!$C$13="",'Inputs & Assumptions'!$C$12,'Inputs & Assumptions'!$C$13)) -> 0.30305236 | E26: =IFERROR(IF('Inputs & Assumptions'!$C$13="",'Inputs & Assumptions'!$C$12,'Inputs & Assumptions'!$C$13)+(IF('Inputs & Assumptions'!$C$27="",SLOPE(Schedules!J25:L25,Schedules!J12:L12),'Inputs & Assumptions'!$C$27)-(IF('Inputs & Assumptions'!$C$13="",'Inputs & Assumptions'!$C$12,'Inputs & Assumptions'!$C$13)))*0.5^(3/(IF('Inputs & Assumptions'!$C$16="",'Inputs & Assumptions'!$C$15,'Inputs & Assumptions'!$C$16))),IF('Inputs & Assumptions'!$C$13="",'Inputs & Assumptions'!$C$12,'Inputs & Assumptions'!$C$13)) -> 0.27545493 | F26: =IFERROR(IF('Inputs & Assumptions'!$C$13="",'Inputs & Assumptions'!$C$12,'Inputs & Assumptions'!$C$13)+(IF('Inputs & Assumptions'!$C$27="",SLOPE(Schedules!J25:L25,Schedules!J12:L12),'Inputs & Assumptions'!$C$27)-(IF('Inputs & Assumptions'!$C$13="",'Inputs & Assumptions'!$C$12,'Inputs & Assumptions'!$C$13)))*0.5^(4/(IF('Inputs & Assumptions'!$C$16="",'Inputs & Assumptions'!$C$15,'Inputs & Assumptions'!$C$16))),IF('Inputs & Assumptions'!$C$13="",'Inputs & Assumptions'!$C$12,'Inputs & Assumptions'!$C$13)) -> 0.25086842 | G26: =IFERROR(IF('Inputs & Assumptions'!$C$13="",'Inputs & Assumptions'!$C$12,'Inputs & Assumptions'!$C$13)+(IF('Inputs & Assumptions'!$C$27="",SLOPE(Schedules!J25:L25,Schedules!J12:L12),'Inputs & Assumptions'!$C$27)-(IF('Inputs & Assumptions'!$C$13="",'Inputs & Assumptions'!$C$12,'Inputs & Assumptions'!$C$13)))*0.5^(5/(IF('Inputs & Assumptions'!$C$16="",'Inputs & Assumptions'!$C$15,'Inputs & Assumptions'!$C$16))),IF('Inputs & Assumptions'!$C$13="",'Inputs & Assumptions'!$C$12,'Inputs & Assumptions'!$C$13)) -> 0.22896433 | H26: =IFERROR(IF('Inputs & Assumptions'!$C$13="",'Inputs & Assumptions'!$C$12,'Inputs & Assumptions'!$C$13)+(IF('Inputs & Assumptions'!$C$27="",SLOPE(Schedules!J25:L25,Schedules!J12:L12),'Inputs & Assumptions'!$C$27)-(IF('Inputs & Assumptions'!$C$13="",'Inputs & Assumptions'!$C$12,'Inputs & Assumptions'!$C$13)))*0.5^(6/(IF('Inputs & Assumptions'!$C$16="",'Inputs & Assumptions'!$C$15,'Inputs & Assumptions'!$C$16))),IF('Inputs & Assumptions'!$C$13="",'Inputs & Assumptions'!$C$12,'Inputs & Assumptions'!$C$13)) -> 0.20945 | I26: =IFERROR(IF('Inputs & Assumptions'!$C$13="",'Inputs & Assumptions'!$C$12,'Inputs & Assumptions'!$C$13)+(IF('Inputs & Assumptions'!$C$27="",SLOPE(Schedules!J25:L25,Schedules!J12:L12),'Inputs & Assumptions'!$C$27)-(IF('Inputs & Assumptions'!$C$13="",'Inputs & Assumptions'!$C$12,'Inputs & Assumptions'!$C$13)))*0.5^(7/(IF('Inputs & Assumptions'!$C$16="",'Inputs & Assumptions'!$C$15,'Inputs & Assumptions'!$C$16))),IF('Inputs & Assumptions'!$C$13="",'Inputs & Assumptions'!$C$12,'Inputs & Assumptions'!$C$13)) -> 0.19206471 | J26: =IFERROR(IF('Inputs & Assumptions'!$C$13="",'Inputs & Assumptions'!$C$12,'Inputs & Assumptions'!$C$13)+(IF('Inputs & Assumptions'!$C$27="",SLOPE(Schedules!J25:L25,Schedules!J12:L12),'Inputs & Assumptions'!$C$27)-(IF('Inputs & Assumptions'!$C$13="",'Inputs & Assumptions'!$C$12,'Inputs & Assumptions'!$C$13)))*0.5^(8/(IF('Inputs & Assumptions'!$C$16="",'Inputs & Assumptions'!$C$15,'Inputs & Assumptions'!$C$16))),IF('Inputs & Assumptions'!$C$13="",'Inputs & Assumptions'!$C$12,'Inputs & Assumptions'!$C$13)) -> 0.17657618 | K26: =IFERROR(IF('Inputs & Assumptions'!$C$13="",'Inputs & Assumptions'!$C$12,'Inputs & Assumptions'!$C$13)+(IF('Inputs & Assumptions'!$C$27="",SLOPE(Schedules!J25:L25,Schedules!J12:L12),'Inputs & Assumptions'!$C$27)-(IF('Inputs & Assumptions'!$C$13="",'Inputs & Assumptions'!$C$12,'Inputs & Assumptions'!$C$13)))*0.5^(9/(IF('Inputs & Assumptions'!$C$16="",'Inputs & Assumptions'!$C$15,'Inputs & Assumptions'!$C$16))),IF('Inputs & Assumptions'!$C$13="",'Inputs & Assumptions'!$C$12,'Inputs & Assumptions'!$C$13)) -> 0.16277747 | L26: =IFERROR(IF('Inputs & Assumptions'!$C$13="",'Inputs & Assumptions'!$C$12,'Inputs & Assumptions'!$C$13)+(IF('Inputs & Assumptions'!$C$27="",SLOPE(Schedules!J25:L25,Schedules!J12:L12),'Inputs & Assumptions'!$C$27)-(IF('Inputs & Assumptions'!$C$13="",'Inputs & Assumptions'!$C$12,'Inputs & Assumptions'!$C$13)))*0.5^(10/(IF('Inputs & Assumptions'!$C$16="",'Inputs & Assumptions'!$C$15,'Inputs & Assumptions'!$C$16))),IF('Inputs & Assumptions'!$C$13="",'Inputs & Assumptions'!$C$12,'Inputs & Assumptions'!$C$13)) -> 0.15048421
B27: INPUT: Services Revenue Growth % (overrides the trend/fade) | C27: 0.3688
A29: # | B29: Working Capital Schedule Drivers
B31: Suggested: COGS % of Revenue, last 3yr avg | C31: =AVERAGE(Schedules!J33:L33) -> -0.6252848 | D31: =$C$31 -> -0.6252848 | E31: =$C$31 -> -0.6252848 | F31: =$C$31 -> -0.6252848 | G31: =$C$31 -> -0.6252848 | H31: =$C$31 -> -0.6252848 | I31: =$C$31 -> -0.6252848 | J31: =$C$31 -> -0.6252848 | K31: =$C$31 -> -0.6252848 | L31: =$C$31 -> -0.6252848
B32: INPUT: COGS % of Revenue
B34: Suggested: Days Sales Outstanding, last 3yr avg | C34: =AVERAGE(Schedules!J40:L40) -> 101.14164 | D34: =$C$34 -> 101.14164 | E34: =$C$34 -> 101.14164 | F34: =$C$34 -> 101.14164 | G34: =$C$34 -> 101.14164 | H34: =$C$34 -> 101.14164 | I34: =$C$34 -> 101.14164 | J34: =$C$34 -> 101.14164 | K34: =$C$34 -> 101.14164 | L34: =$C$34 -> 101.14164
B35: INPUT: Days Sales Outstanding
B37: Suggested: Days Inventory Outstanding, last 3yr avg | C37: =AVERAGE(Schedules!J41:L41) -> 185.93274 | D37: =$C$37 -> 185.93274 | E37: =$C$37 -> 185.93274 | F37: =$C$37 -> 185.93274 | G37: =$C$37 -> 185.93274 | H37: =$C$37 -> 185.93274 | I37: =$C$37 -> 185.93274 | J37: =$C$37 -> 185.93274 | K37: =$C$37 -> 185.93274 | L37: =$C$37 -> 185.93274
B38: INPUT: Days Inventory Outstanding
B40: Suggested: Days Payable Outstanding, last 3yr avg | C40: =AVERAGE(Schedules!J42:L42) -> 135.49783 | D40: =$C$40 -> 135.49783 | E40: =$C$40 -> 135.49783 | F40: =$C$40 -> 135.49783 | G40: =$C$40 -> 135.49783 | H40: =$C$40 -> 135.49783 | I40: =$C$40 -> 135.49783 | J40: =$C$40 -> 135.49783 | K40: =$C$40 -> 135.49783 | L40: =$C$40 -> 135.49783
B41: INPUT: Days Payable Outstanding
A43: # | B43: PP&E Schedule Drivers
B45: Suggested: Additions Growth % -- log-linear, last 3yr, half-life decay to terminal | C45: =(IF('Inputs & Assumptions'!$C$13="",'Inputs & Assumptions'!$C$12,'Inputs & Assumptions'!$C$13)+(IF('Inputs & Assumptions'!$C$46="",MIN(SLOPE(Schedules!J74:L74,Schedules!J70:L70),'WACC Schedule'!$C$21),'Inputs & Assumptions'!$C$46)-(IF('Inputs & Assumptions'!$C$13="",'Inputs & Assumptions'!$C$12,'Inputs & Assumptions'!$C$13)))*0.5^(1/(IF('Inputs & Assumptions'!$C$16="",'Inputs & Assumptions'!$C$15,'Inputs & Assumptions'!$C$16)))) -> 0.047536034 | D45: =(IF('Inputs & Assumptions'!$C$13="",'Inputs & Assumptions'!$C$12,'Inputs & Assumptions'!$C$13)+(IF('Inputs & Assumptions'!$C$46="",MIN(SLOPE(Schedules!J74:L74,Schedules!J70:L70),'WACC Schedule'!$C$21),'Inputs & Assumptions'!$C$46)-(IF('Inputs & Assumptions'!$C$13="",'Inputs & Assumptions'!$C$12,'Inputs & Assumptions'!$C$13)))*0.5^(2/(IF('Inputs & Assumptions'!$C$16="",'Inputs & Assumptions'!$C$15,'Inputs & Assumptions'!$C$16)))) -> 0.047815766 | E45: =(IF('Inputs & Assumptions'!$C$13="",'Inputs & Assumptions'!$C$12,'Inputs & Assumptions'!$C$13)+(IF('Inputs & Assumptions'!$C$46="",MIN(SLOPE(Schedules!J74:L74,Schedules!J70:L70),'WACC Schedule'!$C$21),'Inputs & Assumptions'!$C$46)-(IF('Inputs & Assumptions'!$C$13="",'Inputs & Assumptions'!$C$12,'Inputs & Assumptions'!$C$13)))*0.5^(3/(IF('Inputs & Assumptions'!$C$16="",'Inputs & Assumptions'!$C$15,'Inputs & Assumptions'!$C$16)))) -> 0.048064979 | F45: =(IF('Inputs & Assumptions'!$C$13="",'Inputs & Assumptions'!$C$12,'Inputs & Assumptions'!$C$13)+(IF('Inputs & Assumptions'!$C$46="",MIN(SLOPE(Schedules!J74:L74,Schedules!J70:L70),'WACC Schedule'!$C$21),'Inputs & Assumptions'!$C$46)-(IF('Inputs & Assumptions'!$C$13="",'Inputs & Assumptions'!$C$12,'Inputs & Assumptions'!$C$13)))*0.5^(4/(IF('Inputs & Assumptions'!$C$16="",'Inputs & Assumptions'!$C$15,'Inputs & Assumptions'!$C$16)))) -> 0.048287003 | G45: =(IF('Inputs & Assumptions'!$C$13="",'Inputs & Assumptions'!$C$12,'Inputs & Assumptions'!$C$13)+(IF('Inputs & Assumptions'!$C$46="",MIN(SLOPE(Schedules!J74:L74,Schedules!J70:L70),'WACC Schedule'!$C$21),'Inputs & Assumptions'!$C$46)-(IF('Inputs & Assumptions'!$C$13="",'Inputs & Assumptions'!$C$12,'Inputs & Assumptions'!$C$13)))*0.5^(5/(IF('Inputs & Assumptions'!$C$16="",'Inputs & Assumptions'!$C$15,'Inputs & Assumptions'!$C$16)))) -> 0.048484803 | H45: =(IF('Inputs & Assumptions'!$C$13="",'Inputs & Assumptions'!$C$12,'Inputs & Assumptions'!$C$13)+(IF('Inputs & Assumptions'!$C$46="",MIN(SLOPE(Schedules!J74:L74,Schedules!J70:L70),'WACC Schedule'!$C$21),'Inputs & Assumptions'!$C$46)-(IF('Inputs & Assumptions'!$C$13="",'Inputs & Assumptions'!$C$12,'Inputs & Assumptions'!$C$13)))*0.5^(6/(IF('Inputs & Assumptions'!$C$16="",'Inputs & Assumptions'!$C$15,'Inputs & Assumptions'!$C$16)))) -> 0.048661023 | I45: =(IF('Inputs & Assumptions'!$C$13="",'Inputs & Assumptions'!$C$12,'Inputs & Assumptions'!$C$13)+(IF('Inputs & Assumptions'!$C$46="",MIN(SLOPE(Schedules!J74:L74,Schedules!J70:L70),'WACC Schedule'!$C$21),'Inputs & Assumptions'!$C$46)-(IF('Inputs & Assumptions'!$C$13="",'Inputs & Assumptions'!$C$12,'Inputs & Assumptions'!$C$13)))*0.5^(7/(IF('Inputs & Assumptions'!$C$16="",'Inputs & Assumptions'!$C$15,'Inputs & Assumptions'!$C$16)))) -> 0.048818017 | J45: =(IF('Inputs & Assumptions'!$C$13="",'Inputs & Assumptions'!$C$12,'Inputs & Assumptions'!$C$13)+(IF('Inputs & Assumptions'!$C$46="",MIN(SLOPE(Schedules!J74:L74,Schedules!J70:L70),'WACC Schedule'!$C$21),'Inputs & Assumptions'!$C$46)-(IF('Inputs & Assumptions'!$C$13="",'Inputs & Assumptions'!$C$12,'Inputs & Assumptions'!$C$13)))*0.5^(8/(IF('Inputs & Assumptions'!$C$16="",'Inputs & Assumptions'!$C$15,'Inputs & Assumptions'!$C$16)))) -> 0.048957883 | K45: =(IF('Inputs & Assumptions'!$C$13="",'Inputs & Assumptions'!$C$12,'Inputs & Assumptions'!$C$13)+(IF('Inputs & Assumptions'!$C$46="",MIN(SLOPE(Schedules!J74:L74,Schedules!J70:L70),'WACC Schedule'!$C$21),'Inputs & Assumptions'!$C$46)-(IF('Inputs & Assumptions'!$C$13="",'Inputs & Assumptions'!$C$12,'Inputs & Assumptions'!$C$13)))*0.5^(9/(IF('Inputs & Assumptions'!$C$16="",'Inputs & Assumptions'!$C$15,'Inputs & Assumptions'!$C$16)))) -> 0.04908249 | L45: =(IF('Inputs & Assumptions'!$C$13="",'Inputs & Assumptions'!$C$12,'Inputs & Assumptions'!$C$13)+(IF('Inputs & Assumptions'!$C$46="",MIN(SLOPE(Schedules!J74:L74,Schedules!J70:L70),'WACC Schedule'!$C$21),'Inputs & Assumptions'!$C$46)-(IF('Inputs & Assumptions'!$C$13="",'Inputs & Assumptions'!$C$12,'Inputs & Assumptions'!$C$13)))*0.5^(10/(IF('Inputs & Assumptions'!$C$16="",'Inputs & Assumptions'!$C$15,'Inputs & Assumptions'!$C$16)))) -> 0.049193501
B46: INPUT: Additions Growth % (overrides the trend/fade)
B48: Suggested: New Asset Useful Life, years -- Ind AS Schedule II general Plant & Machinery default (15yr, generic regulatory constant) | C48: 15
B49: INPUT: New Asset Useful Life, years
B51: Suggested: Impairment, % of Opening PP&E, last 3yr avg | C51: =AVERAGE(Schedules!J77:L77) -> 0 | D51: =$C$51 -> 0 | E51: =$C$51 -> 0 | F51: =$C$51 -> 0 | G51: =$C$51 -> 0 | H51: =$C$51 -> 0 | I51: =$C$51 -> 0 | J51: =$C$51 -> 0 | K51: =$C$51 -> 0 | L51: =$C$51 -> 0
B52: INPUT: Impairment % of Opening PP&E
B54: Suggested: Other Changes, % of Opening PP&E, last 3yr avg | C54: =AVERAGE(Schedules!J78:L78) -> 0 | D54: =$C$54 -> 0 | E54: =$C$54 -> 0 | F54: =$C$54 -> 0 | G54: =$C$54 -> 0 | H54: =$C$54 -> 0 | I54: =$C$54 -> 0 | J54: =$C$54 -> 0 | K54: =$C$54 -> 0 | L54: =$C$54 -> 0
B55: INPUT: Other Changes % of Opening PP&E
B57: Suggested: Disposals, % of Opening PP&E, last 3yr avg | C57: =AVERAGE(Schedules!J79:L79) -> 0 | D57: =$C$57 -> 0 | E57: =$C$57 -> 0 | F57: =$C$57 -> 0 | G57: =$C$57 -> 0 | H57: =$C$57 -> 0 | I57: =$C$57 -> 0 | J57: =$C$57 -> 0 | K57: =$C$57 -> 0 | L57: =$C$57 -> 0
B58: INPUT: Disposals % of Opening PP&E
A60: # | B60: Debt Schedule Drivers
B62: Suggested: Include Lease Liabilities as Quasi-Debt (1=yes, 0=no) -- default 0 (Borrowings only) | C62: 0
B63: INPUT: Include Lease Liabilities as Quasi-Debt (1=yes, 0=no)
...

Sheet HIST_CON
A1: Suzlon — Derived Financial Model
A2: Green = cross-sheet formula (XLOOKUP against raw data) | Black = same-sheet formula (subtotal/total)
A5: # | B5: Statement of Profit and Loss | E5: FY? | F5: FY2017 | G5: FY2018 | H5: FY2019 | I5: FY2020 | J5: FY2021 | K5: FY2022 | L5: FY2023 | M5: FY2024 | N5: FY2025
B6: Income [Abstract]
C7: Total revenue from operations | E7: =_xlfn.XLOOKUP("RevenueFromOperations",HS_CONSOLIDATED!$C:$C,HS_CONSOLIDATED!D:D,0,0,1) -> 0 | F7: =_xlfn.XLOOKUP("RevenueFromOperations",HS_CONSOLIDATED!$C:$C,HS_CONSOLIDATED!E:E,0,0,1) -> 127143700000 | G7: =_xlfn.XLOOKUP("RevenueFromOperations",HS_CONSOLIDATED!$C:$C,HS_CONSOLIDATED!F:F,0,0,1) -> 83338400000 | H7: =_xlfn.XLOOKUP("RevenueFromOperations",HS_CONSOLIDATED!$C:$C,HS_CONSOLIDATED!G:G,0,0,1) -> 50246900000 | I7: =_xlfn.XLOOKUP("RevenueFromOperations",HS_CONSOLIDATED!$C:$C,HS_CONSOLIDATED!H:H,0,0,1) -> 29728500000 | J7: =_xlfn.XLOOKUP("RevenueFromOperations",HS_CONSOLIDATED!$C:$C,HS_CONSOLIDATED!I:I,0,0,1) -> 33457200000 | K7: =_xlfn.XLOOKUP("RevenueFromOperations",HS_CONSOLIDATED!$C:$C,HS_CONSOLIDATED!J:J,0,0,1) -> 65817800000 | L7: =_xlfn.XLOOKUP("RevenueFromOperations",HS_CONSOLIDATED!$C:$C,HS_CONSOLIDATED!K:K,0,0,1) -> 59705300000 | M7: =_xlfn.XLOOKUP("RevenueFromOperations",HS_CONSOLIDATED!$C:$C,HS_CONSOLIDATED!L:L,0,0,1) -> 65290900000 | N7: =_xlfn.XLOOKUP("RevenueFromOperations",HS_CONSOLIDATED!$C:$C,HS_CONSOLIDATED!M:M,0,0,1) -> 108897400000
C8: Total other income | E8: =_xlfn.XLOOKUP("OtherIncome",HS_CONSOLIDATED!$C:$C,HS_CONSOLIDATED!D:D,0,0,1) -> 0 | F8: =_xlfn.XLOOKUP("OtherIncome",HS_CONSOLIDATED!$C:$C,HS_CONSOLIDATED!E:E,0,0,1) -> 888200000 | G8: =_xlfn.XLOOKUP("OtherIncome",HS_CONSOLIDATED!$C:$C,HS_CONSOLIDATED!F:F,0,0,1) -> 791700000 | H8: =_xlfn.XLOOKUP("OtherIncome",HS_CONSOLIDATED!$C:$C,HS_CONSOLIDATED!G:G,0,0,1) -> 499500000 | I8: =_xlfn.XLOOKUP("OtherIncome",HS_CONSOLIDATED!$C:$C,HS_CONSOLIDATED!H:H,0,0,1) -> 275700000 | J8: =_xlfn.XLOOKUP("OtherIncome",HS_CONSOLIDATED!$C:$C,HS_CONSOLIDATED!I:I,0,0,1) -> 198700000 | K8: =_xlfn.XLOOKUP("OtherIncome",HS_CONSOLIDATED!$C:$C,HS_CONSOLIDATED!J:J,0,0,1) -> 221900000 | L8: =_xlfn.XLOOKUP("OtherIncome",HS_CONSOLIDATED!$C:$C,HS_CONSOLIDATED!K:K,0,0,1) -> 196300000 | M8: =_xlfn.XLOOKUP("OtherIncome",HS_CONSOLIDATED!$C:$C,HS_CONSOLIDATED!L:L,0,0,1) -> 384200000 | N8: =_xlfn.XLOOKUP("OtherIncome",HS_CONSOLIDATED!$C:$C,HS_CONSOLIDATED!M:M,0,0,1) -> 1033900000
C9: Total income | E9: =IFERROR(SUM(E7:E8),0) -> 0 | F9: =IFERROR(SUM(F7:F8),0) -> 128031900000 | G9: =IFERROR(SUM(G7:G8),0) -> 84130100000 | H9: =IFERROR(SUM(H7:H8),0) -> 50746400000 | I9: =IFERROR(SUM(I7:I8),0) -> 30004200000 | J9: =IFERROR(SUM(J7:J8),0) -> 33655900000 | K9: =IFERROR(SUM(K7:K8),0) -> 66039700000 | L9: =IFERROR(SUM(L7:L8),0) -> 59901600000 | ... N9: =IFERROR(SUM(N7:N8),0) -> 109931300000
B10: COGS
C11: Cost of materials consumed | E11: =-_xlfn.XLOOKUP("CostOfMaterialsConsumed",HS_CONSOLIDATED!$C:$C,HS_CONSOLIDATED!D:D,0,0,1) -> 0 | F11: =-_xlfn.XLOOKUP("CostOfMaterialsConsumed",HS_CONSOLIDATED!$C:$C,HS_CONSOLIDATED!E:E,0,0,1) -> -82914400000 | G11: =-_xlfn.XLOOKUP("CostOfMaterialsConsumed",HS_CONSOLIDATED!$C:$C,HS_CONSOLIDATED!F:F,0,0,1) -> -40319900000 | H11: =-_xlfn.XLOOKUP("CostOfMaterialsConsumed",HS_CONSOLIDATED!$C:$C,HS_CONSOLIDATED!G:G,0,0,1) -> -29565000000 | I11: =-_xlfn.XLOOKUP("CostOfMaterialsConsumed",HS_CONSOLIDATED!$C:$C,HS_CONSOLIDATED!H:H,0,0,1) -> -14044100000 | J11: =-_xlfn.XLOOKUP("CostOfMaterialsConsumed",HS_CONSOLIDATED!$C:$C,HS_CONSOLIDATED!I:I,0,0,1) -> -16107500000 | K11: =-_xlfn.XLOOKUP("CostOfMaterialsConsumed",HS_CONSOLIDATED!$C:$C,HS_CONSOLIDATED!J:J,0,0,1) -> -40919500000 | L11: =-_xlfn.XLOOKUP("CostOfMaterialsConsumed",HS_CONSOLIDATED!$C:$C,HS_CONSOLIDATED!K:K,0,0,1) -> -36267600000 | M11: =-_xlfn.XLOOKUP("CostOfMaterialsConsumed",HS_CONSOLIDATED!$C:$C,HS_CONSOLIDATED!L:L,0,0,1) -> -40186500000 | N11: =-_xlfn.XLOOKUP("CostOfMaterialsConsumed",HS_CONSOLIDATED!$C:$C,HS_CONSOLIDATED!M:M,0,0,1) -> -71391700000
C12: Purchases of stock-in-trade | E12: =-_xlfn.XLOOKUP("PurchasesOfStockInTrade",HS_CONSOLIDATED!$C:$C,HS_CONSOLIDATED!D:D,0,0,1) -> 0 | F12: =-_xlfn.XLOOKUP("PurchasesOfStockInTrade",HS_CONSOLIDATED!$C:$C,HS_CONSOLIDATED!E:E,0,0,1) -> 0 | G12: =-_xlfn.XLOOKUP("PurchasesOfStockInTrade",HS_CONSOLIDATED!$C:$C,HS_CONSOLIDATED!F:F,0,0,1) -> -9879500000 | H12: =-_xlfn.XLOOKUP("PurchasesOfStockInTrade",HS_CONSOLIDATED!$C:$C,HS_CONSOLIDATED!G:G,0,0,1) -> 0 | I12: =-_xlfn.XLOOKUP("PurchasesOfStockInTrade",HS_CONSOLIDATED!$C:$C,HS_CONSOLIDATED!H:H,0,0,1) -> 0 | J12: =-_xlfn.XLOOKUP("PurchasesOfStockInTrade",HS_CONSOLIDATED!$C:$C,HS_CONSOLIDATED!I:I,0,0,1) -> 0 | K12: =-_xlfn.XLOOKUP("PurchasesOfStockInTrade",HS_CONSOLIDATED!$C:$C,HS_CONSOLIDATED!J:J,0,0,1) -> 0 | L12: =-_xlfn.XLOOKUP("PurchasesOfStockInTrade",HS_CONSOLIDATED!$C:$C,HS_CONSOLIDATED!K:K,0,0,1) -> 0 | M12: =-_xlfn.XLOOKUP("PurchasesOfStockInTrade",HS_CONSOLIDATED!$C:$C,HS_CONSOLIDATED!L:L,0,0,1) -> 0 | N12: =-_xlfn.XLOOKUP("PurchasesOfStockInTrade",HS_CONSOLIDATED!$C:$C,HS_CONSOLIDATED!M:M,0,0,1) -> 0
C13: Total changes in inventories of finished goods, work-in-progress and stock-in-trade | E13: =-_xlfn.XLOOKUP("ChangesInInventoriesOfFinishedGoodsWorkInProgressAndStockInTrade",HS_CONSOLIDATED!$C:$C,HS_CONSOLIDATED!D:D,0,0,1) -> 0 | F13: =-_xlfn.XLOOKUP("ChangesInInventoriesOfFinishedGoodsWorkInProgressAndStockInTrade",HS_CONSOLIDATED!$C:$C,HS_CONSOLIDATED!E:E,0,0,1) -> 7485500000 | G13: =-_xlfn.XLOOKUP("ChangesInInventoriesOfFinishedGoodsWorkInProgressAndStockInTrade",HS_CONSOLIDATED!$C:$C,HS_CONSOLIDATED!F:F,0,0,1) -> -957700000 | H13: =-_xlfn.XLOOKUP("ChangesInInventoriesOfFinishedGoodsWorkInProgressAndStockInTrade",HS_CONSOLIDATED!$C:$C,HS_CONSOLIDATED!G:G,0,0,1) -> -418500000 | I13: =-_xlfn.XLOOKUP("ChangesInInventoriesOfFinishedGoodsWorkInProgressAndStockInTrade",HS_CONSOLIDATED!$C:$C,HS_CONSOLIDATED!H:H,0,0,1) -> -4691000000 | J13: =-_xlfn.XLOOKUP("ChangesInInventoriesOfFinishedGoodsWorkInProgressAndStockInTrade",HS_CONSOLIDATED!$C:$C,HS_CONSOLIDATED!I:I,0,0,1) -> 334800000 | K13: =-_xlfn.XLOOKUP("ChangesInInventoriesOfFinishedGoodsWorkInProgressAndStockInTrade",HS_CONSOLIDATED!$C:$C,HS_CONSOLIDATED!J:J,0,0,1) -> -2396100000 | L13: =-_xlfn.XLOOKUP("ChangesInInventoriesOfFinishedGoodsWorkInProgressAndStockInTrade",HS_CONSOLIDATED!$C:$C,HS_CONSOLIDATED!K:K,0,0,1) -> -1559000000 | M13: =-_xlfn.XLOOKUP("ChangesInInventoriesOfFinishedGoodsWorkInProgressAndStockInTrade",HS_CONSOLIDATED!$C:$C,HS_CONSOLIDATED!L:L,0,0,1) -> 365200000 | N13: =-_xlfn.XLOOKUP("ChangesInInventoriesOfFinishedGoodsWorkInProgressAndStockInTrade",HS_CONSOLIDATED!$C:$C,HS_CONSOLIDATED!M:M,0,0,1) -> 2525700000
B14: Gross Profit | E14: =IFERROR(E9+SUM(E11:E13),0) -> 0 | F14: =IFERROR(F9+SUM(F11:F13),0) -> 52603000000 | G14: =IFERROR(G9+SUM(G11:G13),0) -> 32973000000 | H14: =IFERROR(H9+SUM(H11:H13),0) -> 20762900000 | I14: =IFERROR(I9+SUM(I11:I13),0) -> 11269100000 | J14: =IFERROR(J9+SUM(J11:J13),0) -> 17883200000 | K14: =IFERROR(K9+SUM(K11:K13),0) -> 22724100000 | L14: =IFERROR(L9+SUM(L11:L13),0) -> 22075000000 | ... N14: =IFERROR(N9+SUM(N11:N13),0) -> 41065300000
C15: SG&A | E15: =-_xlfn.XLOOKUP("EmployeeBenefitExpense",HS_CONSOLIDATED!$C:$C,HS_CONSOLIDATED!D:D,0,0,1)-_xlfn.XLOOKUP("ExpenditureOnProductionTransportationAndOtherExpenditurePertainingToExplorationAndProductionActivities",HS_CONSOLIDATED!$C:$C,HS_CONSOLIDATED!D:D,0,0,1) -> 0 | F15: =-_xlfn.XLOOKUP("EmployeeBenefitExpense",HS_CONSOLIDATED!$C:$C,HS_CONSOLIDATED!E:E,0,0,1)-_xlfn.XLOOKUP("ExpenditureOnProductionTransportationAndOtherExpenditurePertainingToExplorationAndProductionActivities",HS_CONSOLIDATED!$C:$C,HS_CONSOLIDATED!E:E,0,0,1) -> -10464800000 | G15: =-_xlfn.XLOOKUP("EmployeeBenefitExpense",HS_CONSOLIDATED!$C:$C,HS_CONSOLIDATED!F:F,0,0,1)-_xlfn.XLOOKUP("ExpenditureOnProductionTransportationAndOtherExpenditurePertainingToExplorationAndProductionActivities",HS_CONSOLIDATED!$C:$C,HS_CONSOLIDATED!F:F,0,0,1) -> -8046800000 | H15: =-_xlfn.XLOOKUP("EmployeeBenefitExpense",HS_CONSOLIDATED!$C:$C,HS_CONSOLIDATED!G:G,0,0,1)-_xlfn.XLOOKUP("ExpenditureOnProductionTransportationAndOtherExpenditurePertainingToExplorationAndProductionActivities",HS_CONSOLIDATED!$C:$C,HS_CONSOLIDATED!G:G,0,0,1) -> -8741600000 | I15: =-_xlfn.XLOOKUP("EmployeeBenefitExpense",HS_CONSOLIDATED!$C:$C,HS_CONSOLIDATED!H:H,0,0,1)-_xlfn.XLOOKUP("ExpenditureOnProductionTransportationAndOtherExpenditurePertainingToExplorationAndProductionActivities",HS_CONSOLIDATED!$C:$C,HS_CONSOLIDATED!H:H,0,0,1) -> -7962500000 | J15: =-_xlfn.XLOOKUP("EmployeeBenefitExpense",HS_CONSOLIDATED!$C:$C,HS_CONSOLIDATED!I:I,0,0,1)-_xlfn.XLOOKUP("ExpenditureOnProductionTransportationAndOtherExpenditurePertainingToExplorationAndProductionActivities",HS_CONSOLIDATED!$C:$C,HS_CONSOLIDATED!I:I,0,0,1) -> -5532100000 | K15: =-_xlfn.XLOOKUP("EmployeeBenefitExpense",HS_CONSOLIDATED!$C:$C,HS_CONSOLIDATED!J:J,0,0,1)-_xlfn.XLOOKUP("ExpenditureOnProductionTransportationAndOtherExpenditurePertainingToExplorationAndProductionActivities",HS_CONSOLIDATED!$C:$C,HS_CONSOLIDATED!J:J,0,0,1) -> -5453600000 | L15: =-_xlfn.XLOOKUP("EmployeeBenefitExpense",HS_CONSOLIDATED!$C:$C,HS_CONSOLIDATED!K:K,0,0,1)-_xlfn.XLOOKUP("ExpenditureOnProductionTransportationAndOtherExpenditurePertainingToExplorationAndProductionActivities",HS_CONSOLIDATED!$C:$C,HS_CONSOLIDATED!K:K,0,0,1) -> -6092200000 | M15: =-_xlfn.XLOOKUP("EmployeeBenefitExpense",HS_CONSOLIDATED!$C:$C,HS_CONSOLIDATED!L:L,0,0,1)-_xlfn.XLOOKUP("ExpenditureOnProductionTransportationAndOtherExpenditurePertainingToExplorationAndProductionActivities",HS_CONSOLIDATED!$C:$C,HS_CONSOLIDATED!L:L,0,0,1) -> -7029000000 | N15: =-_xlfn.XLOOKUP("EmployeeBenefitExpense",HS_CONSOLIDATED!$C:$C,HS_CONSOLIDATED!M:M,0,0,1)-_xlfn.XLOOKUP("ExpenditureOnProductionTransportationAndOtherExpenditurePertainingToExplorationAndProductionActivities",HS_CONSOLIDATED!$C:$C,HS_CONSOLIDATED!M:M,0,0,1) -> -9415300000
C16: Total other expenses | E16: =-_xlfn.XLOOKUP("OtherExpenses",HS_CONSOLIDATED!$C:$C,HS_CONSOLIDATED!D:D,0,0,1) -> 0 | F16: =-_xlfn.XLOOKUP("OtherExpenses",HS_CONSOLIDATED!$C:$C,HS_CONSOLIDATED!E:E,0,0,1) -> -16256100000 | G16: =-_xlfn.XLOOKUP("OtherExpenses",HS_CONSOLIDATED!$C:$C,HS_CONSOLIDATED!F:F,0,0,1) -> -14103900000 | H16: =-_xlfn.XLOOKUP("OtherExpenses",HS_CONSOLIDATED!$C:$C,HS_CONSOLIDATED!G:G,0,0,1) -> -11609300000 | I16: =-_xlfn.XLOOKUP("OtherExpenses",HS_CONSOLIDATED!$C:$C,HS_CONSOLIDATED!H:H,0,0,1) -> -11628200000 | J16: =-_xlfn.XLOOKUP("OtherExpenses",HS_CONSOLIDATED!$C:$C,HS_CONSOLIDATED!I:I,0,0,1) -> -6809600000 | K16: =-_xlfn.XLOOKUP("OtherExpenses",HS_CONSOLIDATED!$C:$C,HS_CONSOLIDATED!J:J,0,0,1) -> -8154100000 | L16: =-_xlfn.XLOOKUP("OtherExpenses",HS_CONSOLIDATED!$C:$C,HS_CONSOLIDATED!K:K,0,0,1) -> -7467300000 | M16: =-_xlfn.XLOOKUP("OtherExpenses",HS_CONSOLIDATED!$C:$C,HS_CONSOLIDATED!L:L,0,0,1) -> -8151800000 | N16: =-_xlfn.XLOOKUP("OtherExpenses",HS_CONSOLIDATED!$C:$C,HS_CONSOLIDATED!M:M,0,0,1) -> -12043800000
B17: EBITDA | E17: =IFERROR(SUM(E14:E16),0) -> 0 | F17: =IFERROR(SUM(F14:F16),0) -> 25882100000 | G17: =IFERROR(SUM(G14:G16),0) -> 10822300000 | H17: =IFERROR(SUM(H14:H16),0) -> 412000000 | I17: =IFERROR(SUM(I14:I16),0) -> -8321600000 | J17: =IFERROR(SUM(J14:J16),0) -> 5541500000 | K17: =IFERROR(SUM(K14:K16),0) -> 9116400000 | L17: =IFERROR(SUM(L14:L16),0) -> 8515500000 | ... N17: =IFERROR(SUM(N14:N16),0) -> 19606200000
C18: D&A | E18: =-_xlfn.XLOOKUP("DepreciationDepletionAndAmortisationExpense",HS_CONSOLIDATED!$C:$C,HS_CONSOLIDATED!D:D,0,0,1) -> 0 | F18: =-_xlfn.XLOOKUP("DepreciationDepletionAndAmortisationExpense",HS_CONSOLIDATED!$C:$C,HS_CONSOLIDATED!E:E,0,0,1) -> -3890300000 | G18: =-_xlfn.XLOOKUP("DepreciationDepletionAndAmortisationExpense",HS_CONSOLIDATED!$C:$C,HS_CONSOLIDATED!F:F,0,0,1) -> -3416100000 | H18: =-_xlfn.XLOOKUP("DepreciationDepletionAndAmortisationExpense",HS_CONSOLIDATED!$C:$C,HS_CONSOLIDATED!G:G,0,0,1) -> -3418500000 | I18: =-_xlfn.XLOOKUP("DepreciationDepletionAndAmortisationExpense",HS_CONSOLIDATED!$C:$C,HS_CONSOLIDATED!H:H,0,0,1) -> -4186100000 | J18: =-_xlfn.XLOOKUP("DepreciationDepletionAndAmortisationExpense",HS_CONSOLIDATED!$C:$C,HS_CONSOLIDATED!I:I,0,0,1) -> -2583800000 | K18: =-_xlfn.XLOOKUP("DepreciationDepletionAndAmortisationExpense",HS_CONSOLIDATED!$C:$C,HS_CONSOLIDATED!J:J,0,0,1) -> -2598400000 | L18: =-_xlfn.XLOOKUP("DepreciationDepletionAndAmortisationExpense",HS_CONSOLIDATED!$C:$C,HS_CONSOLIDATED!K:K,0,0,1) -> -2596800000 | M18: =-_xlfn.XLOOKUP("DepreciationDepletionAndAmortisationExpense",HS_CONSOLIDATED!$C:$C,HS_CONSOLIDATED!L:L,0,0,1) -> -1896000000 | N18: =-_xlfn.XLOOKUP("DepreciationDepletionAndAmortisationExpense",HS_CONSOLIDATED!$C:$C,HS_CONSOLIDATED!M:M,0,0,1) -> -2591900000
B19: EBIT | E19: =IFERROR(SUM(E17:E18),0) -> 0 | F19: =IFERROR(SUM(F17:F18),0) -> 21991800000 | G19: =IFERROR(SUM(G17:G18),0) -> 7406200000 | H19: =IFERROR(SUM(H17:H18),0) -> -3006500000 | I19: =IFERROR(SUM(I17:I18),0) -> -12507700000 | J19: =IFERROR(SUM(J17:J18),0) -> 2957700000 | K19: =IFERROR(SUM(K17:K18),0) -> 6518000000 | L19: =IFERROR(SUM(L17:L18),0) -> 5918700000 | ... N19: =IFERROR(SUM(N17:N18),0) -> 17014300000
C20: Total finance costs | E20: =-_xlfn.XLOOKUP("FinanceCosts",HS_CONSOLIDATED!$C:$C,HS_CONSOLIDATED!D:D,0,0,1) -> 0 | F20: =-_xlfn.XLOOKUP("FinanceCosts",HS_CONSOLIDATED!$C:$C,HS_CONSOLIDATED!E:E,0,0,1) -> -12875900000 | G20: =-_xlfn.XLOOKUP("FinanceCosts",HS_CONSOLIDATED!$C:$C,HS_CONSOLIDATED!F:F,0,0,1) -> -15809800000 | H20: =-_xlfn.XLOOKUP("FinanceCosts",HS_CONSOLIDATED!$C:$C,HS_CONSOLIDATED!G:G,0,0,1) -> -12699100000 | I20: =-_xlfn.XLOOKUP("FinanceCosts",HS_CONSOLIDATED!$C:$C,HS_CONSOLIDATED!H:H,0,0,1) -> -13672900000 | J20: =-_xlfn.XLOOKUP("FinanceCosts",HS_CONSOLIDATED!$C:$C,HS_CONSOLIDATED!I:I,0,0,1) -> -9962600000 | K20: =-_xlfn.XLOOKUP("FinanceCosts",HS_CONSOLIDATED!$C:$C,HS_CONSOLIDATED!J:J,0,0,1) -> -7345200000 | L20: =-_xlfn.XLOOKUP("FinanceCosts",HS_CONSOLIDATED!$C:$C,HS_CONSOLIDATED!K:K,0,0,1) -> -4207600000 | M20: =-_xlfn.XLOOKUP("FinanceCosts",HS_CONSOLIDATED!$C:$C,HS_CONSOLIDATED!L:L,0,0,1) -> -1643200000 | N20: =-_xlfn.XLOOKUP("FinanceCosts",HS_CONSOLIDATED!$C:$C,HS_CONSOLIDATED!M:M,0,0,1) -> -2548000000
C21: Exceptional items before tax | E21: =_xlfn.XLOOKUP("ExceptionalItemsBeforeTax",HS_CONSOLIDATED!$C:$C,HS_CONSOLIDATED!D:D,0,0,1) -> 0 | F21: =_xlfn.XLOOKUP("ExceptionalItemsBeforeTax",HS_CONSOLIDATED!$C:$C,HS_CONSOLIDATED!E:E,0,0,1) -> 0 | G21: =_xlfn.XLOOKUP("ExceptionalItemsBeforeTax",HS_CONSOLIDATED!$C:$C,HS_CONSOLIDATED!F:F,0,0,1) -> 4496200000 | H21: =_xlfn.XLOOKUP("ExceptionalItemsBeforeTax",HS_CONSOLIDATED!$C:$C,HS_CONSOLIDATED!G:G,0,0,1) -> 275700000 | I21: =_xlfn.XLOOKUP("ExceptionalItemsBeforeTax",HS_CONSOLIDATED!$C:$C,HS_CONSOLIDATED!H:H,0,0,1) -> -658900000 | J21: =_xlfn.XLOOKUP("ExceptionalItemsBeforeTax",HS_CONSOLIDATED!$C:$C,HS_CONSOLIDATED!I:I,0,0,1) -> 8054600000 | K21: =_xlfn.XLOOKUP("ExceptionalItemsBeforeTax",HS_CONSOLIDATED!$C:$C,HS_CONSOLIDATED!J:J,0,0,1) -> 831200000 | L21: =_xlfn.XLOOKUP("ExceptionalItemsBeforeTax",HS_CONSOLIDATED!$C:$C,HS_CONSOLIDATED!K:K,0,0,1) -> 27206000000 | M21: =_xlfn.XLOOKUP("ExceptionalItemsBeforeTax",HS_CONSOLIDATED!$C:$C,HS_CONSOLIDATED!L:L,0,0,1) -> -538900000 | N21: =_xlfn.XLOOKUP("ExceptionalItemsBeforeTax",HS_CONSOLIDATED!$C:$C,HS_CONSOLIDATED!M:M,0,0,1) -> 0
B22: EBT | E22: =IFERROR(SUM(E19:E21),0) -> 0 | F22: =IFERROR(SUM(F19:F21),0) -> 9115900000 | G22: =IFERROR(SUM(G19:G21),0) -> -3907400000 | H22: =IFERROR(SUM(H19:H21),0) -> -15429900000 | I22: =IFERROR(SUM(I19:I21),0) -> -26839500000 | J22: =IFERROR(SUM(J19:J21),0) -> 1049700000 | K22: =IFERROR(SUM(K19:K21),0) -> 4000000 | L22: =IFERROR(SUM(L19:L21),0) -> 28917100000 | ... N22: =IFERROR(SUM(N19:N21),0) -> 14466300000
C23: Total current tax | E23: =-_xlfn.XLOOKUP("CurrentTax",HS_CONSOLIDATED!$C:$C,HS_CONSOLIDATED!D:D,0,0,1) -> 0 | F23: =-_xlfn.XLOOKUP("CurrentTax",HS_CONSOLIDATED!$C:$C,HS_CONSOLIDATED!E:E,0,0,1) -> -117000000 | G23: =-_xlfn.XLOOKUP("CurrentTax",HS_CONSOLIDATED!$C:$C,HS_CONSOLIDATED!F:F,0,0,1) -> 15600000 | H23: =-_xlfn.XLOOKUP("CurrentTax",HS_CONSOLIDATED!$C:$C,HS_CONSOLIDATED!G:G,0,0,1) -> -30900000 | I23: =-_xlfn.XLOOKUP("CurrentTax",HS_CONSOLIDATED!$C:$C,HS_CONSOLIDATED!H:H,0,0,1) -> -74400000 | J23: =-_xlfn.XLOOKUP("CurrentTax",HS_CONSOLIDATED!$C:$C,HS_CONSOLIDATED!I:I,0,0,1) -> -46300000 | K23: =-_xlfn.XLOOKUP("CurrentTax",HS_CONSOLIDATED!$C:$C,HS_CONSOLIDATED!J:J,0,0,1) -> -1840700000 | L23: =-_xlfn.XLOOKUP("CurrentTax",HS_CONSOLIDATED!$C:$C,HS_CONSOLIDATED!K:K,0,0,1) -> -46100000 | M23: =-_xlfn.XLOOKUP("CurrentTax",HS_CONSOLIDATED!$C:$C,HS_CONSOLIDATED!L:L,0,0,1) -> -29000000 | N23: =-_xlfn.XLOOKUP("CurrentTax",HS_CONSOLIDATED!$C:$C,HS_CONSOLIDATED!M:M,0,0,1) -> -144200000
C24: Deferred tax | E24: =-_xlfn.XLOOKUP("DeferredTax",HS_CONSOLIDATED!$C:$C,HS_CONSOLIDATED!D:D,0,0,1) -> 0 | F24: =-_xlfn.XLOOKUP("DeferredTax",HS_CONSOLIDATED!$C:$C,HS_CONSOLIDATED!E:E,0,0,1) -> 0 | G24: =-_xlfn.XLOOKUP("DeferredTax",HS_CONSOLIDATED!$C:$C,HS_CONSOLIDATED!F:F,0,0,1) -> 0 | H24: =-_xlfn.XLOOKUP("DeferredTax",HS_CONSOLIDATED!$C:$C,HS_CONSOLIDATED!G:G,0,0,1) -> 149900000 | I24: =-_xlfn.XLOOKUP("DeferredTax",HS_CONSOLIDATED!$C:$C,HS_CONSOLIDATED!H:H,0,0,1) -> 0 | J24: =-_xlfn.XLOOKUP("DeferredTax",HS_CONSOLIDATED!$C:$C,HS_CONSOLIDATED!I:I,0,0,1) -> 0 | K24: =-_xlfn.XLOOKUP("DeferredTax",HS_CONSOLIDATED!$C:$C,HS_CONSOLIDATED!J:J,0,0,1) -> 174800000 | L24: =-_xlfn.XLOOKUP("DeferredTax",HS_CONSOLIDATED!$C:$C,HS_CONSOLIDATED!K:K,0,0,1) -> 1900000 | M24: =-_xlfn.XLOOKUP("DeferredTax",HS_CONSOLIDATED!$C:$C,HS_CONSOLIDATED!L:L,0,0,1) -> 37600000 | N24: =-_xlfn.XLOOKUP("DeferredTax",HS_CONSOLIDATED!$C:$C,HS_CONSOLIDATED!M:M,0,0,1) -> 6394200000
C25: Total tax expense | E25: =IFERROR(SUM(E23:E24),0) -> 0 | F25: =IFERROR(SUM(F23:F24),0) -> -117000000 | G25: =IFERROR(SUM(G23:G24),0) -> 15600000 | H25: =IFERROR(SUM(H23:H24),0) -> 119000000 | I25: =IFERROR(SUM(I23:I24),0) -> -74400000 | J25: =IFERROR(SUM(J23:J24),0) -> -46300000 | K25: =IFERROR(SUM(K23:K24),0) -> -1665900000 | L25: =IFERROR(SUM(L23:L24),0) -> -44200000 | ... N25: =IFERROR(SUM(N23:N24),0) -> 6250000000
B26: NETINCOME | E26: =IFERROR(E25+E22,0) -> 0 | F26: =IFERROR(F25+F22,0) -> 8998900000 | G26: =IFERROR(G25+G22,0) -> -3891800000 | H26: =IFERROR(H25+H22,0) -> -15310900000 | I26: =IFERROR(I25+I22,0) -> -26913900000 | J26: =IFERROR(J25+J22,0) -> 1003400000 | K26: =IFERROR(K25+K22,0) -> -1661900000 | L26: =IFERROR(L25+L22,0) -> 28872900000 | ... N26: =IFERROR(N25+N22,0) -> 20716300000
A27: # | B27: Balance Sheet
B28: Assets [Abstract]
B29: Non-current assets [Abstract]
C30: Operating
D31: Property, plant and equipment at end of period | E31: =_xlfn.XLOOKUP("PropertyPlantAndEquipment",HS_CONSOLIDATED!$C:$C,HS_CONSOLIDATED!D:D,0,0,1) -> 0 | F31: =_xlfn.XLOOKUP("PropertyPlantAndEquipment",HS_CONSOLIDATED!$C:$C,HS_CONSOLIDATED!E:E,0,0,1) -> 14201800000 | G31: =_xlfn.XLOOKUP("PropertyPlantAndEquipment",HS_CONSOLIDATED!$C:$C,HS_CONSOLIDATED!F:F,0,0,1) -> 12673200000 | H31: =_xlfn.XLOOKUP("PropertyPlantAndEquipment",HS_CONSOLIDATED!$C:$C,HS_CONSOLIDATED!G:G,0,0,1) -> 11473200000 | I31: =_xlfn.XLOOKUP("PropertyPlantAndEquipment",HS_CONSOLIDATED!$C:$C,HS_CONSOLIDATED!H:H,0,0,1) -> 10484300000 | J31: =_xlfn.XLOOKUP("PropertyPlantAndEquipment",HS_CONSOLIDATED!$C:$C,HS_CONSOLIDATED!I:I,0,0,1) -> 9353100000 | K31: =_xlfn.XLOOKUP("PropertyPlantAndEquipment",HS_CONSOLIDATED!$C:$C,HS_CONSOLIDATED!J:J,0,0,1) -> 9073300000 | L31: =_xlfn.XLOOKUP("PropertyPlantAndEquipment",HS_CONSOLIDATED!$C:$C,HS_CONSOLIDATED!K:K,0,0,1) -> 7784500000 | M31: =_xlfn.XLOOKUP("PropertyPlantAndEquipment",HS_CONSOLIDATED!$C:$C,HS_CONSOLIDATED!L:L,0,0,1) -> 8095100000 | N31: =_xlfn.XLOOKUP("PropertyPlantAndEquipment",HS_CONSOLIDATED!$C:$C,HS_CONSOLIDATED!M:M,0,0,1) -> 8220600000
D32: Capital work-in-progress | E32: =_xlfn.XLOOKUP("CapitalWorkInProgress",HS_CONSOLIDATED!$C:$C,HS_CONSOLIDATED!D:D,0,0,1) -> 0 | F32: =_xlfn.XLOOKUP("CapitalWorkInProgress",HS_CONSOLIDATED!$C:$C,HS_CONSOLIDATED!E:E,0,0,1) -> 1185600000 | G32: =_xlfn.XLOOKUP("CapitalWorkInProgress",HS_CONSOLIDATED!$C:$C,HS_CONSOLIDATED!F:F,0,0,1) -> 1734200000 | H32: =_xlfn.XLOOKUP("CapitalWorkInProgress",HS_CONSOLIDATED!$C:$C,HS_CONSOLIDATED!G:G,0,0,1) -> 2183300000 | I32: =_xlfn.XLOOKUP("CapitalWorkInProgress",HS_CONSOLIDATED!$C:$C,HS_CONSOLIDATED!H:H,0,0,1) -> 1100800000 | J32: =_xlfn.XLOOKUP("CapitalWorkInProgress",HS_CONSOLIDATED!$C:$C,HS_CONSOLIDATED!I:I,0,0,1) -> 1039300000 | K32: =_xlfn.XLOOKUP("CapitalWorkInProgress",HS_CONSOLIDATED!$C:$C,HS_CONSOLIDATED!J:J,0,0,1) -> 152100000 | L32: =_xlfn.XLOOKUP("CapitalWorkInProgress",HS_CONSOLIDATED!$C:$C,HS_CONSOLIDATED!K:K,0,0,1) -> 25700000 | M32: =_xlfn.XLOOKUP("CapitalWorkInProgress",HS_CONSOLIDATED!$C:$C,HS_CONSOLIDATED!L:L,0,0,1) -> 162100000 | N32: =_xlfn.XLOOKUP("CapitalWorkInProgress",HS_CONSOLIDATED!$C:$C,HS_CONSOLIDATED!M:M,0,0,1) -> 886700000
D33: Goodwill at end of period | E33: =_xlfn.XLOOKUP("Goodwill",HS_CONSOLIDATED!$C:$C,HS_CONSOLIDATED!D:D,0,0,1) -> 0 | F33: =_xlfn.XLOOKUP("Goodwill",HS_CONSOLIDATED!$C:$C,HS_CONSOLIDATED!E:E,0,0,1) -> 76200000 | G33: =_xlfn.XLOOKUP("Goodwill",HS_CONSOLIDATED!$C:$C,HS_CONSOLIDATED!F:F,0,0,1) -> 76300000 | H33: =_xlfn.XLOOKUP("Goodwill",HS_CONSOLIDATED!$C:$C,HS_CONSOLIDATED!G:G,0,0,1) -> 76300000 | I33: =_xlfn.XLOOKUP("Goodwill",HS_CONSOLIDATED!$C:$C,HS_CONSOLIDATED!H:H,0,0,1) -> 76300000 | J33: =_xlfn.XLOOKUP("Goodwill",HS_CONSOLIDATED!$C:$C,HS_CONSOLIDATED!I:I,0,0,1) -> 76300000 | K33: =_xlfn.XLOOKUP("Goodwill",HS_CONSOLIDATED!$C:$C,HS_CONSOLIDATED!J:J,0,0,1) -> 0 | L33: =_xlfn.XLOOKUP("Goodwill",HS_CONSOLIDATED!$C:$C,HS_CONSOLIDATED!K:K,0,0,1) -> 0 | M33: =_xlfn.XLOOKUP("Goodwill",HS_CONSOLIDATED!$C:$C,HS_CONSOLIDATED!L:L,0,0,1) -> 0 | N33: =_xlfn.XLOOKUP("Goodwill",HS_CONSOLIDATED!$C:$C,HS_CONSOLIDATED!M:M,0,0,1) -> 4798300000
D34: Other intangible assets at end of period | E34: =_xlfn.XLOOKUP("OtherIntangibleAssets",HS_CONSOLIDATED!$C:$C,HS_CONSOLIDATED!D:D,0,0,1) -> 0 | F34: =_xlfn.XLOOKUP("OtherIntangibleAssets",HS_CONSOLIDATED!$C:$C,HS_CONSOLIDATED!E:E,0,0,1) -> 2033500000 | G34: =_xlfn.XLOOKUP("OtherIntangibleAssets",HS_CONSOLIDATED!$C:$C,HS_CONSOLIDATED!F:F,0,0,1) -> 1471200000 | H34: =_xlfn.XLOOKUP("OtherIntangibleAssets",HS_CONSOLIDATED!$C:$C,HS_CONSOLIDATED!G:G,0,0,1) -> 3274400000 | I34: =_xlfn.XLOOKUP("OtherIntangibleAssets",HS_CONSOLIDATED!$C:$C,HS_CONSOLIDATED!H:H,0,0,1) -> 2675000000 | J34: =_xlfn.XLOOKUP("OtherIntangibleAssets",HS_CONSOLIDATED!$C:$C,HS_CONSOLIDATED!I:I,0,0,1) -> 1904600000 | K34: =_xlfn.XLOOKUP("OtherIntangibleAssets",HS_CONSOLIDATED!$C:$C,HS_CONSOLIDATED!J:J,0,0,1) -> 1211100000 | L34: =_xlfn.XLOOKUP("OtherIntangibleAssets",HS_CONSOLIDATED!$C:$C,HS_CONSOLIDATED!K:K,0,0,1) -> 584800000 | M34: =_xlfn.XLOOKUP("OtherIntangibleAssets",HS_CONSOLIDATED!$C:$C,HS_CONSOLIDATED!L:L,0,0,1) -> 499400000 | N34: =_xlfn.XLOOKUP("OtherIntangibleAssets",HS_CONSOLIDATED!$C:$C,HS_CONSOLIDATED!M:M,0,0,1) -> 4519200000
D35: Intangible assets under development | E35: =_xlfn.XLOOKUP("IntangibleAssetsUnderDevelopment",HS_CONSOLIDATED!$C:$C,HS_CONSOLIDATED!D:D,0,0,1) -> 0 | F35: =_xlfn.XLOOKUP("IntangibleAssetsUnderDevelopment",HS_CONSOLIDATED!$C:$C,HS_CONSOLIDATED!E:E,0,0,1) -> 874300000 | G35: =_xlfn.XLOOKUP("IntangibleAssetsUnderDevelopment",HS_CONSOLIDATED!$C:$C,HS_CONSOLIDATED!F:F,0,0,1) -> 1798200000 | H35: =_xlfn.XLOOKUP("IntangibleAssetsUnderDevelopment",HS_CONSOLIDATED!$C:$C,HS_CONSOLIDATED!G:G,0,0,1) -> 104100000 | I35: =_xlfn.XLOOKUP("IntangibleAssetsUnderDevelopment",HS_CONSOLIDATED!$C:$C,HS_CONSOLIDATED!H:H,0,0,1) -> 123000000 | J35: =_xlfn.XLOOKUP("IntangibleAssetsUnderDevelopment",HS_CONSOLIDATED!$C:$C,HS_CONSOLIDATED!I:I,0,0,1) -> 35200000 | K35: =_xlfn.XLOOKUP("IntangibleAssetsUnderDevelopment",HS_CONSOLIDATED!$C:$C,HS_CONSOLIDATED!J:J,0,0,1) -> 44200000 | L35: =_xlfn.XLOOKUP("IntangibleAssetsUnderDevelopment",HS_CONSOLIDATED!$C:$C,HS_CONSOLIDATED!K:K,0,0,1) -> 34300000 | M35: =_xlfn.XLOOKUP("IntangibleAssetsUnderDevelopment",HS_CONSOLIDATED!$C:$C,HS_CONSOLIDATED!L:L,0,0,1) -> 35100000 | N35: =_xlfn.XLOOKUP("IntangibleAssetsUnderDevelopment",HS_CONSOLIDATED!$C:$C,HS_CONSOLIDATED!M:M,0,0,1) -> 164300000
D36: Trade receivables, non-current | E36: =_xlfn.XLOOKUP("TradeReceivablesNoncurrent",HS_CONSOLIDATED!$C:$C,HS_CONSOLIDATED!D:D,0,0,1) -> 0 | F36: =_xlfn.XLOOKUP("TradeReceivablesNoncurrent",HS_CONSOLIDATED!$C:$C,HS_CONSOLIDATED!E:E,0,0,1) -> 457700000 | G36: =_xlfn.XLOOKUP("TradeReceivablesNoncurrent",HS_CONSOLIDATED!$C:$C,HS_CONSOLIDATED!F:F,0,0,1) -> 48400000 | H36: =_xlfn.XLOOKUP("TradeReceivablesNoncurrent",HS_CONSOLIDATED!$C:$C,HS_CONSOLIDATED!G:G,0,0,1) -> 0 | I36: =_xlfn.XLOOKUP("TradeReceivablesNoncurrent",HS_CONSOLIDATED!$C:$C,HS_CONSOLIDATED!H:H,0,0,1) -> 0 | J36: =_xlfn.XLOOKUP("TradeReceivablesNoncurrent",HS_CONSOLIDATED!$C:$C,HS_CONSOLIDATED!I:I,0,0,1) -> 0 | K36: =_xlfn.XLOOKUP("TradeReceivablesNoncurrent",HS_CONSOLIDATED!$C:$C,HS_CONSOLIDATED!J:J,0,0,1) -> 0 | L36: =_xlfn.XLOOKUP("TradeReceivablesNoncurrent",HS_CONSOLIDATED!$C:$C,HS_CONSOLIDATED!K:K,0,0,1) -> 0 | M36: =_xlfn.XLOOKUP("TradeReceivablesNoncurrent",HS_CONSOLIDATED!$C:$C,HS_CONSOLIDATED!L:L,0,0,1) -> 0 | N36: =_xlfn.XLOOKUP("TradeReceivablesNoncurrent",HS_CONSOLIDATED!$C:$C,HS_CONSOLIDATED!M:M,0,0,1) -> 0
D37: Total other non-current assets | E37: =_xlfn.XLOOKUP("OtherNoncurrentAssets",HS_CONSOLIDATED!$C:$C,HS_CONSOLIDATED!D:D,0,0,1) -> 0 | F37: =_xlfn.XLOOKUP("OtherNoncurrentAssets",HS_CONSOLIDATED!$C:$C,HS_CONSOLIDATED!E:E,0,0,1) -> 1661600000 | G37: =_xlfn.XLOOKUP("OtherNoncurrentAssets",HS_CONSOLIDATED!$C:$C,HS_CONSOLIDATED!F:F,0,0,1) -> 1393800000 | H37: =_xlfn.XLOOKUP("OtherNoncurrentAssets",HS_CONSOLIDATED!$C:$C,HS_CONSOLIDATED!G:G,0,0,1) -> 1038400000 | I37: =_xlfn.XLOOKUP("OtherNoncurrentAssets",HS_CONSOLIDATED!$C:$C,HS_CONSOLIDATED!H:H,0,0,1) -> 510500000 | J37: =_xlfn.XLOOKUP("OtherNoncurrentAssets",HS_CONSOLIDATED!$C:$C,HS_CONSOLIDATED!I:I,0,0,1) -> 544600000 | K37: =_xlfn.XLOOKUP("OtherNoncurrentAssets",HS_CONSOLIDATED!$C:$C,HS_CONSOLIDATED!J:J,0,0,1) -> 292400000 | L37: =_xlfn.XLOOKUP("OtherNoncurrentAssets",HS_CONSOLIDATED!$C:$C,HS_CONSOLIDATED!K:K,0,0,1) -> 402200000 | M37: =_xlfn.XLOOKUP("OtherNoncurrentAssets",HS_CONSOLIDATED!$C:$C,HS_CONSOLIDATED!L:L,0,0,1) -> 784300000 | N37: =_xlfn.XLOOKUP("OtherNoncurrentAssets",HS_CONSOLIDATED!$C:$C,HS_CONSOLIDATED!M:M,0,0,1) -> 751400000
C38: Total Operating | E38: =IFERROR(SUM(E31:E37),0) -> 0 | F38: =IFERROR(SUM(F31:F37),0) -> 20490700000 | G38: =IFERROR(SUM(G31:G37),0) -> 19195300000 | H38: =IFERROR(SUM(H31:H37),0) -> 18149700000 | I38: =IFERROR(SUM(I31:I37),0) -> 14969900000 | J38: =IFERROR(SUM(J31:J37),0) -> 12953100000 | K38: =IFERROR(SUM(K31:K37),0) -> 10773100000 | L38: =IFERROR(SUM(L31:L37),0) -> 8831500000 | ... N38: =IFERROR(SUM(N31:N37),0) -> 19340500000
C39: Non-Operating
D40: Investment property at end of period | E40: =_xlfn.XLOOKUP("InvestmentProperty",HS_CONSOLIDATED!$C:$C,HS_CONSOLIDATED!D:D,0,0,1) -> 0 | F40: =_xlfn.XLOOKUP("InvestmentProperty",HS_CONSOLIDATED!$C:$C,HS_CONSOLIDATED!E:E,0,0,1) -> 341400000 | G40: =_xlfn.XLOOKUP("InvestmentProperty",HS_CONSOLIDATED!$C:$C,HS_CONSOLIDATED!F:F,0,0,1) -> 407900000 | H40: =_xlfn.XLOOKUP("InvestmentProperty",HS_CONSOLIDATED!$C:$C,HS_CONSOLIDATED!G:G,0,0,1) -> 373600000 | I40: =_xlfn.XLOOKUP("InvestmentProperty",HS_CONSOLIDATED!$C:$C,HS_CONSOLIDATED!H:H,0,0,1) -> 346700000 | J40: =_xlfn.XLOOKUP("InvestmentProperty",HS_CONSOLIDATED!$C:$C,HS_CONSOLIDATED!I:I,0,0,1) -> 326400000 | K40: =_xlfn.XLOOKUP("InvestmentProperty",HS_CONSOLIDATED!$C:$C,HS_CONSOLIDATED!J:J,0,0,1) -> 308600000 | L40: =_xlfn.XLOOKUP("InvestmentProperty",HS_CONSOLIDATED!$C:$C,HS_CONSOLIDATED!K:K,0,0,1) -> 292100000 | M40: =_xlfn.XLOOKUP("InvestmentProperty",HS_CONSOLIDATED!$C:$C,HS_CONSOLIDATED!L:L,0,0,1) -> 270100000 | N40: =_xlfn.XLOOKUP("InvestmentProperty",HS_CONSOLIDATED!$C:$C,HS_CONSOLIDATED!M:M,0,0,1) -> 257500000
D41: Investments accounted for using equity method | E41: =_xlfn.XLOOKUP("InvestmentsAccountedForUsingEquityMethod",HS_CONSOLIDATED!$C:$C,HS_CONSOLIDATED!D:D,0,0,1) -> 0 | F41: =_xlfn.XLOOKUP("InvestmentsAccountedForUsingEquityMethod",HS_CONSOLIDATED!$C:$C,HS_CONSOLIDATED!E:E,0,0,1) -> 0 | G41: =_xlfn.XLOOKUP("InvestmentsAccountedForUsingEquityMethod",HS_CONSOLIDATED!$C:$C,HS_CONSOLIDATED!F:F,0,0,1) -> 668600000 | H41: =_xlfn.XLOOKUP("InvestmentsAccountedForUsingEquityMethod",HS_CONSOLIDATED!$C:$C,HS_CONSOLIDATED!G:G,0,0,1) -> 203000000 | I41: =_xlfn.XLOOKUP("InvestmentsAccountedForUsingEquityMethod",HS_CONSOLIDATED!$C:$C,HS_CONSOLIDATED!H:H,0,0,1) -> 197100000 | J41: =_xlfn.XLOOKUP("InvestmentsAccountedForUsingEquityMethod",HS_CONSOLIDATED!$C:$C,HS_CONSOLIDATED!I:I,0,0,1) -> 229700000 | K41: =_xlfn.XLOOKUP("InvestmentsAccountedForUsingEquityMethod",HS_CONSOLIDATED!$C:$C,HS_CONSOLIDATED!J:J,0,0,1) -> 0 | L41: =_xlfn.XLOOKUP("InvestmentsAccountedForUsingEquityMethod",HS_CONSOLIDATED!$C:$C,HS_CONSOLIDATED!K:K,0,0,1) -> 0 | M41: =_xlfn.XLOOKUP("InvestmentsAccountedForUsingEquityMethod",HS_CONSOLIDATED!$C:$C,HS_CONSOLIDATED!L:L,0,0,1) -> 0 | N41: =_xlfn.XLOOKUP("InvestmentsAccountedForUsingEquityMethod",HS_CONSOLIDATED!$C:$C,HS_CONSOLIDATED!M:M,0,0,1) -> 0
D42: Non-current investments | E42: =_xlfn.XLOOKUP("NoncurrentInvestments",HS_CONSOLIDATED!$C:$C,HS_CONSOLIDATED!D:D,0,0,1) -> 0 | F42: =_xlfn.XLOOKUP("NoncurrentInvestments",HS_CONSOLIDATED!$C:$C,HS_CONSOLIDATED!E:E,0,0,1) -> 1885500000 | G42: =_xlfn.XLOOKUP("NoncurrentInvestments",HS_CONSOLIDATED!$C:$C,HS_CONSOLIDATED!F:F,0,0,1) -> 1300000 | H42: =_xlfn.XLOOKUP("NoncurrentInvestments",HS_CONSOLIDATED!$C:$C,HS_CONSOLIDATED!G:G,0,0,1) -> 1300000 | I42: =_xlfn.XLOOKUP("NoncurrentInvestments",HS_CONSOLIDATED!$C:$C,HS_CONSOLIDATED!H:H,0,0,1) -> 300000 | J42: =_xlfn.XLOOKUP("NoncurrentInvestments",HS_CONSOLIDATED!$C:$C,HS_CONSOLIDATED!I:I,0,0,1) -> 300000 | K42: =_xlfn.XLOOKUP("NoncurrentInvestments",HS_CONSOLIDATED!$C:$C,HS_CONSOLIDATED!J:J,0,0,1) -> 300000 | L42: =_xlfn.XLOOKUP("NoncurrentInvestments",HS_CONSOLIDATED!$C:$C,HS_CONSOLIDATED!K:K,0,0,1) -> 300000 | M42: =_xlfn.XLOOKUP("NoncurrentInvestments",HS_CONSOLIDATED!$C:$C,HS_CONSOLIDATED!L:L,0,0,1) -> 300000 | N42: =_xlfn.XLOOKUP("NoncurrentInvestments",HS_CONSOLIDATED!$C:$C,HS_CONSOLIDATED!M:M,0,0,1) -> 300000
...

Sheet HIST_STAND
A1: Suzlon — Derived Financial Model
A2: Green = cross-sheet formula (XLOOKUP against raw data) | Black = same-sheet formula (subtotal/total)
A5: # | B5: Statement of Profit and Loss | E5: FY? | F5: FY2017 | G5: FY2018 | H5: FY2019 | I5: FY2020 | J5: FY2021 | K5: FY2022 | L5: FY2023 | M5: FY2024 | N5: FY2025
B6: Income [Abstract]
C7: Total revenue from operations | E7: =_xlfn.XLOOKUP("RevenueFromOperations",HS_STANDALONE!$C:$C,HS_STANDALONE!D:D,0,0,1) -> 0 | F7: =_xlfn.XLOOKUP("RevenueFromOperations",HS_STANDALONE!$C:$C,HS_STANDALONE!E:E,0,0,1) -> 92456800000 | G7: =_xlfn.XLOOKUP("RevenueFromOperations",HS_STANDALONE!$C:$C,HS_STANDALONE!F:F,0,0,1) -> 61664800000 | H7: =_xlfn.XLOOKUP("RevenueFromOperations",HS_STANDALONE!$C:$C,HS_STANDALONE!G:G,0,0,1) -> 25435000000 | I7: =_xlfn.XLOOKUP("RevenueFromOperations",HS_STANDALONE!$C:$C,HS_STANDALONE!H:H,0,0,1) -> 3759500000 | J7: =_xlfn.XLOOKUP("RevenueFromOperations",HS_STANDALONE!$C:$C,HS_STANDALONE!I:I,0,0,1) -> 12473100000 | K7: =_xlfn.XLOOKUP("RevenueFromOperations",HS_STANDALONE!$C:$C,HS_STANDALONE!J:J,0,0,1) -> 40400400000 | L7: =_xlfn.XLOOKUP("RevenueFromOperations",HS_STANDALONE!$C:$C,HS_STANDALONE!K:K,0,0,1) -> 35904400000 | M7: =_xlfn.XLOOKUP("RevenueFromOperations",HS_STANDALONE!$C:$C,HS_STANDALONE!L:L,0,0,1) -> 38602500000 | N7: =_xlfn.XLOOKUP("RevenueFromOperations",HS_STANDALONE!$C:$C,HS_STANDALONE!M:M,0,0,1) -> 101977200000
C8: Total other income | E8: =_xlfn.XLOOKUP("OtherIncome",HS_STANDALONE!$C:$C,HS_STANDALONE!D:D,0,0,1) -> 0 | F8: =_xlfn.XLOOKUP("OtherIncome",HS_STANDALONE!$C:$C,HS_STANDALONE!E:E,0,0,1) -> 4009700000 | G8: =_xlfn.XLOOKUP("OtherIncome",HS_STANDALONE!$C:$C,HS_STANDALONE!F:F,0,0,1) -> 3691600000 | H8: =_xlfn.XLOOKUP("OtherIncome",HS_STANDALONE!$C:$C,HS_STANDALONE!G:G,0,0,1) -> 4359800000 | I8: =_xlfn.XLOOKUP("OtherIncome",HS_STANDALONE!$C:$C,HS_STANDALONE!H:H,0,0,1) -> 2361800000 | J8: =_xlfn.XLOOKUP("OtherIncome",HS_STANDALONE!$C:$C,HS_STANDALONE!I:I,0,0,1) -> 697500000 | K8: =_xlfn.XLOOKUP("OtherIncome",HS_STANDALONE!$C:$C,HS_STANDALONE!J:J,0,0,1) -> 630200000 | L8: =_xlfn.XLOOKUP("OtherIncome",HS_STANDALONE!$C:$C,HS_STANDALONE!K:K,0,0,1) -> 1922200000 | M8: =_xlfn.XLOOKUP("OtherIncome",HS_STANDALONE!$C:$C,HS_STANDALONE!L:L,0,0,1) -> 1928800000 | N8: =_xlfn.XLOOKUP("OtherIncome",HS_STANDALONE!$C:$C,HS_STANDALONE!M:M,0,0,1) -> 1023100000
C9: Total income | E9: =IFERROR(SUM(E7:E8),0) -> 0 | F9: =IFERROR(SUM(F7:F8),0) -> 96466500000 | G9: =IFERROR(SUM(G7:G8),0) -> 65356400000 | H9: =IFERROR(SUM(H7:H8),0) -> 29794800000 | I9: =IFERROR(SUM(I7:I8),0) -> 6121300000 | J9: =IFERROR(SUM(J7:J8),0) -> 13170600000 | K9: =IFERROR(SUM(K7:K8),0) -> 41030600000 | L9: =IFERROR(SUM(L7:L8),0) -> 37826600000 | ... N9: =IFERROR(SUM(N7:N8),0) -> 103000300000
B10: COGS
C11: Cost of materials consumed | E11: =-_xlfn.XLOOKUP("CostOfMaterialsConsumed",HS_STANDALONE!$C:$C,HS_STANDALONE!D:D,0,0,1) -> 0 | F11: =-_xlfn.XLOOKUP("CostOfMaterialsConsumed",HS_STANDALONE!$C:$C,HS_STANDALONE!E:E,0,0,1) -> -58734400000 | G11: =-_xlfn.XLOOKUP("CostOfMaterialsConsumed",HS_STANDALONE!$C:$C,HS_STANDALONE!F:F,0,0,1) -> -27451000000 | H11: =-_xlfn.XLOOKUP("CostOfMaterialsConsumed",HS_STANDALONE!$C:$C,HS_STANDALONE!G:G,0,0,1) -> -15179200000 | I11: =-_xlfn.XLOOKUP("CostOfMaterialsConsumed",HS_STANDALONE!$C:$C,HS_STANDALONE!H:H,0,0,1) -> -2730600000 | J11: =-_xlfn.XLOOKUP("CostOfMaterialsConsumed",HS_STANDALONE!$C:$C,HS_STANDALONE!I:I,0,0,1) -> -6855100000 | K11: =-_xlfn.XLOOKUP("CostOfMaterialsConsumed",HS_STANDALONE!$C:$C,HS_STANDALONE!J:J,0,0,1) -> -30843300000 | L11: =-_xlfn.XLOOKUP("CostOfMaterialsConsumed",HS_STANDALONE!$C:$C,HS_STANDALONE!K:K,0,0,1) -> -26629700000 | M11: =-_xlfn.XLOOKUP("CostOfMaterialsConsumed",HS_STANDALONE!$C:$C,HS_STANDALONE!L:L,0,0,1) -> -28531300000 | N11: =-_xlfn.XLOOKUP("CostOfMaterialsConsumed",HS_STANDALONE!$C:$C,HS_STANDALONE!M:M,0,0,1) -> -69868900000
C12: Purchases of stock-in-trade | E12: =-_xlfn.XLOOKUP("PurchasesOfStockInTrade",HS_STANDALONE!$C:$C,HS_STANDALONE!D:D,0,0,1) -> 0 | F12: =-_xlfn.XLOOKUP("PurchasesOfStockInTrade",HS_STANDALONE!$C:$C,HS_STANDALONE!E:E,0,0,1) -> -4919900000 | G12: =-_xlfn.XLOOKUP("PurchasesOfStockInTrade",HS_STANDALONE!$C:$C,HS_STANDALONE!F:F,0,0,1) -> -9879500000 | H12: =-_xlfn.XLOOKUP("PurchasesOfStockInTrade",HS_STANDALONE!$C:$C,HS_STANDALONE!G:G,0,0,1) -> -58100000 | I12: =-_xlfn.XLOOKUP("PurchasesOfStockInTrade",HS_STANDALONE!$C:$C,HS_STANDALONE!H:H,0,0,1) -> 0 | J12: =-_xlfn.XLOOKUP("PurchasesOfStockInTrade",HS_STANDALONE!$C:$C,HS_STANDALONE!I:I,0,0,1) -> 0 | K12: =-_xlfn.XLOOKUP("PurchasesOfStockInTrade",HS_STANDALONE!$C:$C,HS_STANDALONE!J:J,0,0,1) -> 0 | L12: =-_xlfn.XLOOKUP("PurchasesOfStockInTrade",HS_STANDALONE!$C:$C,HS_STANDALONE!K:K,0,0,1) -> 0 | M12: =-_xlfn.XLOOKUP("PurchasesOfStockInTrade",HS_STANDALONE!$C:$C,HS_STANDALONE!L:L,0,0,1) -> 0 | N12: =-_xlfn.XLOOKUP("PurchasesOfStockInTrade",HS_STANDALONE!$C:$C,HS_STANDALONE!M:M,0,0,1) -> 0
C13: Total changes in inventories of finished goods, work-in-progress and stock-in-trade | E13: =-_xlfn.XLOOKUP("ChangesInInventoriesOfFinishedGoodsWorkInProgressAndStockInTrade",HS_STANDALONE!$C:$C,HS_STANDALONE!D:D,0,0,1) -> 0 | F13: =-_xlfn.XLOOKUP("ChangesInInventoriesOfFinishedGoodsWorkInProgressAndStockInTrade",HS_STANDALONE!$C:$C,HS_STANDALONE!E:E,0,0,1) -> 8235700000 | G13: =-_xlfn.XLOOKUP("ChangesInInventoriesOfFinishedGoodsWorkInProgressAndStockInTrade",HS_STANDALONE!$C:$C,HS_STANDALONE!F:F,0,0,1) -> -3853000000 | H13: =-_xlfn.XLOOKUP("ChangesInInventoriesOfFinishedGoodsWorkInProgressAndStockInTrade",HS_STANDALONE!$C:$C,HS_STANDALONE!G:G,0,0,1) -> -1960000000 | I13: =-_xlfn.XLOOKUP("ChangesInInventoriesOfFinishedGoodsWorkInProgressAndStockInTrade",HS_STANDALONE!$C:$C,HS_STANDALONE!H:H,0,0,1) -> -1083100000 | J13: =-_xlfn.XLOOKUP("ChangesInInventoriesOfFinishedGoodsWorkInProgressAndStockInTrade",HS_STANDALONE!$C:$C,HS_STANDALONE!I:I,0,0,1) -> -630100000 | K13: =-_xlfn.XLOOKUP("ChangesInInventoriesOfFinishedGoodsWorkInProgressAndStockInTrade",HS_STANDALONE!$C:$C,HS_STANDALONE!J:J,0,0,1) -> -96700000 | L13: =-_xlfn.XLOOKUP("ChangesInInventoriesOfFinishedGoodsWorkInProgressAndStockInTrade",HS_STANDALONE!$C:$C,HS_STANDALONE!K:K,0,0,1) -> -775300000 | M13: =-_xlfn.XLOOKUP("ChangesInInventoriesOfFinishedGoodsWorkInProgressAndStockInTrade",HS_STANDALONE!$C:$C,HS_STANDALONE!L:L,0,0,1) -> 452900000 | N13: =-_xlfn.XLOOKUP("ChangesInInventoriesOfFinishedGoodsWorkInProgressAndStockInTrade",HS_STANDALONE!$C:$C,HS_STANDALONE!M:M,0,0,1) -> 2691700000
B14: Gross Profit | E14: =IFERROR(E9+SUM(E11:E13),0) -> 0 | F14: =IFERROR(F9+SUM(F11:F13),0) -> 41047900000 | G14: =IFERROR(G9+SUM(G11:G13),0) -> 24172900000 | H14: =IFERROR(H9+SUM(H11:H13),0) -> 12597500000 | I14: =IFERROR(I9+SUM(I11:I13),0) -> 2307600000 | J14: =IFERROR(J9+SUM(J11:J13),0) -> 5685400000 | K14: =IFERROR(K9+SUM(K11:K13),0) -> 10090600000 | L14: =IFERROR(L9+SUM(L11:L13),0) -> 10421600000 | ... N14: =IFERROR(N9+SUM(N11:N13),0) -> 35823100000
